Workbook

Sheet Bets
A1: fixture_id | B1: home_team | C1: away_team | D1: home_team_odds | E1: away_team_odds | F1: draw_odds | G1: Round 1
G2: Bet 1 | K2: Bet 2 | O2: Bet 3 | S2: Bet 4
G3: prediction_type | H3: prediction_selection | I3: prediction_odds | J3: result | K3: prediction_type | L3: prediction_selection | M3: prediction_odds | N3: result | O3: prediction_type | P3: prediction_selection | Q3: prediction_odds | R3: result | S3: prediction_type | T3: prediction_selection | U3: prediction_odds | V3: result
A4: 1 | B4: =VLOOKUP($A4,Fixtures!$A$2:$H$49,2) -> Russia | C4: =VLOOKUP($A4,Fixtures!$A$2:$H$49,3) -> Saudi Arabia | D4: =VLOOKUP($A4,Fixtures!$A$2:$H$49,6) -> 1.4 | E4: =VLOOKUP($A4,Fixtures!$A$2:$H$49,8) -> 9 | F4: =VLOOKUP($A4,Fixtures!$A$2:$H$49,7) -> 4 | G4: favourite | H4: =_xludf.IFS(I4=$D4,$B4,I4=$E4,$C4,I4=$F4,"Draw",I4="","") -> #NAME? | I4: =_xludf.IFS(G4="home",$D4,G4="away",$E4,G4="draw",$F4,G4="favourite",MIN($D4:$F4),G4="outsider",MAX($D4:$F4),G4="random",INDEX($D4:$F4,1,RANDBETWEEN(1,3)),G4="","") -> #NAME? | K4: outsider | L4: =_xludf.IFS(M4=$D4,$B4,M4=$E4,$C4,M4=$F4,"Draw",M4="","") -> #NAME? | M4: =_xludf.IFS(K4="home",$D4,K4="away",$E4,K4="draw",$F4,K4="favourite",MIN($D4:$F4),K4="outsider",MAX($D4:$F4),K4="random",INDEX($D4:$F4,1,RANDBETWEEN(1,3)),K4="","") -> #NAME? | O4: favourite | P4: =_xludf.IFS(Q4=$D4,$B4,Q4=$E4,$C4,Q4=$F4,"Draw",Q4="","") -> #NAME? | Q4: =_xludf.IFS(O4="home",$D4,O4="away",$E4,O4="draw",$F4,O4="favourite",MIN($D4:$F4),O4="outsider",MAX($D4:$F4),O4="random",INDEX($D4:$F4,1,RANDBETWEEN(1,3)),O4="","") -> #NAME? | S4: outsider | T4: =_xludf.IFS(U4=$D4,$B4,U4=$E4,$C4,U4=$F4,"Draw",U4="","") -> #NAME? | U4: =_xludf.IFS(S4="home",$D4,S4="away",$E4,S4="draw",$F4,S4="favourite",MIN($D4:$F4),S4="outsider",MAX($D4:$F4),S4="random",INDEX($D4:$F4,1,RANDBETWEEN(1,3)),S4="","") -> #NAME?
A5: 2 | B5: =VLOOKUP($A5,Fixtures!$A$2:$H$49,2) -> Egypt | C5: =VLOOKUP($A5,Fixtures!$A$2:$H$49,3) -> Uruguay | D5: =VLOOKUP($A5,Fixtures!$A$2:$H$49,6) -> 7 | E5: =VLOOKUP($A5,Fixtures!$A$2:$H$49,8) -> 1.57 | F5: =VLOOKUP($A5,Fixtures!$A$2:$H$49,7) -> 3.5 | G5: favourite | H5: =_xludf.IFS(I5=$D5,$B5,I5=$E5,$C5,I5=$F5,"Draw",I5="","") -> #NAME? | I5: =_xludf.IFS(G5="home",$D5,G5="away",$E5,G5="draw",$F5,G5="favourite",MIN($D5:$F5),G5="outsider",MAX($D5:$F5),G5="random",INDEX($D5:$F5,1,RANDBETWEEN(1,3)),G5="","") -> #NAME? | K5: outsider | L5: =_xludf.IFS(M5=$D5,$B5,M5=$E5,$C5,M5=$F5,"Draw",M5="","") -> #NAME? | M5: =_xludf.IFS(K5="home",$D5,K5="away",$E5,K5="draw",$F5,K5="favourite",MIN($D5:$F5),K5="outsider",MAX($D5:$F5),K5="random",INDEX($D5:$F5,1,RANDBETWEEN(1,3)),K5="","") -> #NAME? | O5: favourite | P5: =_xludf.IFS(Q5=$D5,$B5,Q5=$E5,$C5,Q5=$F5,"Draw",Q5="","") -> #NAME? | Q5: =_xludf.IFS(O5="home",$D5,O5="away",$E5,O5="draw",$F5,O5="favourite",MIN($D5:$F5),O5="outsider",MAX($D5:$F5),O5="random",INDEX($D5:$F5,1,RANDBETWEEN(1,3)),O5="","") -> #NAME? | S5: outsider | T5: =_xludf.IFS(U5=$D5,$B5,U5=$E5,$C5,U5=$F5,"Draw",U5="","") -> #NAME? | U5: =_xludf.IFS(S5="home",$D5,S5="away",$E5,S5="draw",$F5,S5="favourite",MIN($D5:$F5),S5="outsider",MAX($D5:$F5),S5="random",INDEX($D5:$F5,1,RANDBETWEEN(1,3)),S5="","") -> #NAME?
A6: 3 | B6: =VLOOKUP($A6,Fixtures!$A$2:$H$49,2) -> Morocco | C6: =VLOOKUP($A6,Fixtures!$A$2:$H$49,3) -> Iran | D6: =VLOOKUP($A6,Fixtures!$A$2:$H$49,6) -> 2.25 | E6: =VLOOKUP($A6,Fixtures!$A$2:$H$49,8) -> 3.75 | F6: =VLOOKUP($A6,Fixtures!$A$2:$H$49,7) -> 2.88 | G6: favourite | H6: =_xludf.IFS(I6=$D6,$B6,I6=$E6,$C6,I6=$F6,"Draw",I6="","") -> #NAME? | I6: =_xludf.IFS(G6="home",$D6,G6="away",$E6,G6="draw",$F6,G6="favourite",MIN($D6:$F6),G6="outsider",MAX($D6:$F6),G6="random",INDEX($D6:$F6,1,RANDBETWEEN(1,3)),G6="","") -> #NAME? | K6: outsider | L6: =_xludf.IFS(M6=$D6,$B6,M6=$E6,$C6,M6=$F6,"Draw",M6="","") -> #NAME? | M6: =_xludf.IFS(K6="home",$D6,K6="away",$E6,K6="draw",$F6,K6="favourite",MIN($D6:$F6),K6="outsider",MAX($D6:$F6),K6="random",INDEX($D6:$F6,1,RANDBETWEEN(1,3)),K6="","") -> #NAME? | O6: draw | P6: =_xludf.IFS(Q6=$D6,$B6,Q6=$E6,$C6,Q6=$F6,"Draw",Q6="","") -> #NAME? | Q6: =_xludf.IFS(O6="home",$D6,O6="away",$E6,O6="draw",$F6,O6="favourite",MIN($D6:$F6),O6="outsider",MAX($D6:$F6),O6="random",INDEX($D6:$F6,1,RANDBETWEEN(1,3)),O6="","") -> #NAME? | S6: outsider | T6: =_xludf.IFS(U6=$D6,$B6,U6=$E6,$C6,U6=$F6,"Draw",U6="","") -> #NAME? | U6: =_xludf.IFS(S6="home",$D6,S6="away",$E6,S6="draw",$F6,S6="favourite",MIN($D6:$F6),S6="outsider",MAX($D6:$F6),S6="random",INDEX($D6:$F6,1,RANDBETWEEN(1,3)),S6="","") -> #NAME?
A7: 4 | B7: =VLOOKUP($A7,Fixtures!$A$2:$H$49,2) -> Portugal | C7: =VLOOKUP($A7,Fixtures!$A$2:$H$49,3) -> Spain | D7: =VLOOKUP($A7,Fixtures!$A$2:$H$49,6) -> 4.33 | E7: =VLOOKUP($A7,Fixtures!$A$2:$H$49,8) -> 1.91 | F7: =VLOOKUP($A7,Fixtures!$A$2:$H$49,7) -> 3.25 | G7: favourite | H7: =_xludf.IFS(I7=$D7,$B7,I7=$E7,$C7,I7=$F7,"Draw",I7="","") -> #NAME? | I7: =_xludf.IFS(G7="home",$D7,G7="away",$E7,G7="draw",$F7,G7="favourite",MIN($D7:$F7),G7="outsider",MAX($D7:$F7),G7="random",INDEX($D7:$F7,1,RANDBETWEEN(1,3)),G7="","") -> #NAME? | K7: outsider | L7: =_xludf.IFS(M7=$D7,$B7,M7=$E7,$C7,M7=$F7,"Draw",M7="","") -> #NAME? | M7: =_xludf.IFS(K7="home",$D7,K7="away",$E7,K7="draw",$F7,K7="favourite",MIN($D7:$F7),K7="outsider",MAX($D7:$F7),K7="random",INDEX($D7:$F7,1,RANDBETWEEN(1,3)),K7="","") -> #NAME? | O7: favourite | P7: =_xludf.IFS(Q7=$D7,$B7,Q7=$E7,$C7,Q7=$F7,"Draw",Q7="","") -> #NAME? | Q7: =_xludf.IFS(O7="home",$D7,O7="away",$E7,O7="draw",$F7,O7="favourite",MIN($D7:$F7),O7="outsider",MAX($D7:$F7),O7="random",INDEX($D7:$F7,1,RANDBETWEEN(1,3)),O7="","") -> #NAME? | S7: outsider | T7: =_xludf.IFS(U7=$D7,$B7,U7=$E7,$C7,U7=$F7,"Draw",U7="","") -> #NAME? | U7: =_xludf.IFS(S7="home",$D7,S7="away",$E7,S7="draw",$F7,S7="favourite",MIN($D7:$F7),S7="outsider",MAX($D7:$F7),S7="random",INDEX($D7:$F7,1,RANDBETWEEN(1,3)),S7="","") -> #NAME?
A8: 5 | B8: =VLOOKUP($A8,Fixtures!$A$2:$H$49,2) -> France | C8: =VLOOKUP($A8,Fixtures!$A$2:$H$49,3) -> Australia | D8: =VLOOKUP($A8,Fixtures!$A$2:$H$49,6) -> 1.2 | E8: =VLOOKUP($A8,Fixtures!$A$2:$H$49,8) -> 14 | F8: =VLOOKUP($A8,Fixtures!$A$2:$H$49,7) -> 6 | G8: favourite | H8: =_xludf.IFS(I8=$D8,$B8,I8=$E8,$C8,I8=$F8,"Draw",I8="","") -> #NAME? | I8: =_xludf.IFS(G8="home",$D8,G8="away",$E8,G8="draw",$F8,G8="favourite",MIN($D8:$F8),G8="outsider",MAX($D8:$F8),G8="random",INDEX($D8:$F8,1,RANDBETWEEN(1,3)),G8="","") -> #NAME? | K8: outsider | L8: =_xludf.IFS(M8=$D8,$B8,M8=$E8,$C8,M8=$F8,"Draw",M8="","") -> #NAME? | M8: =_xludf.IFS(K8="home",$D8,K8="away",$E8,K8="draw",$F8,K8="favourite",MIN($D8:$F8),K8="outsider",MAX($D8:$F8),K8="random",INDEX($D8:$F8,1,RANDBETWEEN(1,3)),K8="","") -> #NAME? | O8: favourite | P8: =_xludf.IFS(Q8=$D8,$B8,Q8=$E8,$C8,Q8=$F8,"Draw",Q8="","") -> #NAME? | Q8: =_xludf.IFS(O8="home",$D8,O8="away",$E8,O8="draw",$F8,O8="favourite",MIN($D8:$F8),O8="outsider",MAX($D8:$F8),O8="random",INDEX($D8:$F8,1,RANDBETWEEN(1,3)),O8="","") -> #NAME? | S8: outsider | T8: =_xludf.IFS(U8=$D8,$B8,U8=$E8,$C8,U8=$F8,"Draw",U8="","") -> #NAME? | U8: =_xludf.IFS(S8="home",$D8,S8="away",$E8,S8="draw",$F8,S8="favourite",MIN($D8:$F8),S8="outsider",MAX($D8:$F8),S8="random",INDEX($D8:$F8,1,RANDBETWEEN(1,3)),S8="","") -> #NAME?
A9: 6 | B9: =VLOOKUP($A9,Fixtures!$A$2:$H$49,2) -> Argentina | C9: =VLOOKUP($A9,Fixtures!$A$2:$H$49,3) -> Iceland | D9: =VLOOKUP($A9,Fixtures!$A$2:$H$49,6) -> 1.28 | E9: =VLOOKUP($A9,Fixtures!$A$2:$H$49,8) -> 13 | F9: =VLOOKUP($A9,Fixtures!$A$2:$H$49,7) -> 4.5 | G9: favourite | H9: =_xludf.IFS(I9=$D9,$B9,I9=$E9,$C9,I9=$F9,"Draw",I9="","") -> #NAME? | I9: =_xludf.IFS(G9="home",$D9,G9="away",$E9,G9="draw",$F9,G9="favourite",MIN($D9:$F9),G9="outsider",MAX($D9:$F9),G9="random",INDEX($D9:$F9,1,RANDBETWEEN(1,3)),G9="","") -> #NAME? | K9: outsider | L9: =_xludf.IFS(M9=$D9,$B9,M9=$E9,$C9,M9=$F9,"Draw",M9="","") -> #NAME? | M9: =_xludf.IFS(K9="home",$D9,K9="away",$E9,K9="draw",$F9,K9="favourite",MIN($D9:$F9),K9="outsider",MAX($D9:$F9),K9="random",INDEX($D9:$F9,1,RANDBETWEEN(1,3)),K9="","") -> #NAME? | O9: favourite | P9: =_xludf.IFS(Q9=$D9,$B9,Q9=$E9,$C9,Q9=$F9,"Draw",Q9="","") -> #NAME? | Q9: =_xludf.IFS(O9="home",$D9,O9="away",$E9,O9="draw",$F9,O9="favourite",MIN($D9:$F9),O9="outsider",MAX($D9:$F9),O9="random",INDEX($D9:$F9,1,RANDBETWEEN(1,3)),O9="","") -> #NAME? | S9: outsider | T9: =_xludf.IFS(U9=$D9,$B9,U9=$E9,$C9,U9=$F9,"Draw",U9="","") -> #NAME? | U9: =_xludf.IFS(S9="home",$D9,S9="away",$E9,S9="draw",$F9,S9="favourite",MIN($D9:$F9),S9="outsider",MAX($D9:$F9),S9="random",INDEX($D9:$F9,1,RANDBETWEEN(1,3)),S9="","") -> #NAME?
A10: 7 | B10: =VLOOKUP($A10,Fixtures!$A$2:$H$49,2) -> Peru | C10: =VLOOKUP($A10,Fixtures!$A$2:$H$49,3) -> Denmark | D10: =VLOOKUP($A10,Fixtures!$A$2:$H$49,6) -> 3.1 | E10: =VLOOKUP($A10,Fixtures!$A$2:$H$49,8) -> 2.37 | F10: =VLOOKUP($A10,Fixtures!$A$2:$H$49,7) -> 3.1 | G10: favourite | H10: =_xludf.IFS(I10=$D10,$B10,I10=$E10,$C10,I10=$F10,"Draw",I10="","") -> #NAME? | I10: =_xludf.IFS(G10="home",$D10,G10="away",$E10,G10="draw",$F10,G10="favourite",MIN($D10:$F10),G10="outsider",MAX($D10:$F10),G10="random",INDEX($D10:$F10,1,RANDBETWEEN(1,3)),G10="","") -> #NAME? | K10: outsider | L10: =_xludf.IFS(M10=$D10,$B10,M10=$E10,$C10,M10=$F10,"Draw",M10="","") -> #NAME? | M10: =_xludf.IFS(K10="home",$D10,K10="away",$E10,K10="draw",$F10,K10="favourite",MIN($D10:$F10),K10="outsider",MAX($D10:$F10),K10="random",INDEX($D10:$F10,1,RANDBETWEEN(1,3)),K10="","") -> #NAME? | O10: draw | P10: =_xludf.IFS(Q10=$D10,$B10,Q10=$E10,$C10,Q10=$F10,"Draw",Q10="","") -> #NAME? | Q10: =_xludf.IFS(O10="home",$D10,O10="away",$E10,O10="draw",$F10,O10="favourite",MIN($D10:$F10),O10="outsider",MAX($D10:$F10),O10="random",INDEX($D10:$F10,1,RANDBETWEEN(1,3)),O10="","") -> #NAME? | S10: outsider | T10: =_xludf.IFS(U10=$D10,$B10,U10=$E10,$C10,U10=$F10,"Draw",U10="","") -> #NAME? | U10: =_xludf.IFS(S10="home",$D10,S10="away",$E10,S10="draw",$F10,S10="favourite",MIN($D10:$F10),S10="outsider",MAX($D10:$F10),S10="random",INDEX($D10:$F10,1,RANDBETWEEN(1,3)),S10="","") -> #NAME?
A11: 8 | B11: =VLOOKUP($A11,Fixtures!$A$2:$H$49,2) -> Croatia | C11: =VLOOKUP($A11,Fixtures!$A$2:$H$49,3) -> Nigeria | D11: =VLOOKUP($A11,Fixtures!$A$2:$H$49,6) -> 1.67 | E11: =VLOOKUP($A11,Fixtures!$A$2:$H$49,8) -> 5.5 | F11: =VLOOKUP($A11,Fixtures!$A$2:$H$49,7) -> 3.5 | G11: favourite | H11: =_xludf.IFS(I11=$D11,$B11,I11=$E11,$C11,I11=$F11,"Draw",I11="","") -> #NAME? | I11: =_xludf.IFS(G11="home",$D11,G11="away",$E11,G11="draw",$F11,G11="favourite",MIN($D11:$F11),G11="outsider",MAX($D11:$F11),G11="random",INDEX($D11:$F11,1,RANDBETWEEN(1,3)),G11="","") -> #NAME? | K11: outsider | L11: =_xludf.IFS(M11=$D11,$B11,M11=$E11,$C11,M11=$F11,"Draw",M11="","") -> #NAME? | M11: =_xludf.IFS(K11="home",$D11,K11="away",$E11,K11="draw",$F11,K11="favourite",MIN($D11:$F11),K11="outsider",MAX($D11:$F11),K11="random",INDEX($D11:$F11,1,RANDBETWEEN(1,3)),K11="","") -> #NAME? | O11: outsider | P11: =_xludf.IFS(Q11=$D11,$B11,Q11=$E11,$C11,Q11=$F11,"Draw",Q11="","") -> #NAME? | Q11: =_xludf.IFS(O11="home",$D11,O11="away",$E11,O11="draw",$F11,O11="favourite",MIN($D11:$F11),O11="outsider",MAX($D11:$F11),O11="random",INDEX($D11:$F11,1,RANDBETWEEN(1,3)),O11="","") -> #NAME? | S11: outsider | T11: =_xludf.IFS(U11=$D11,$B11,U11=$E11,$C11,U11=$F11,"Draw",U11="","") -> #NAME? | U11: =_xludf.IFS(S11="home",$D11,S11="away",$E11,S11="draw",$F11,S11="favourite",MIN($D11:$F11),S11="outsider",MAX($D11:$F11),S11="random",INDEX($D11:$F11,1,RANDBETWEEN(1,3)),S11="","") -> #NAME?
A12: 9 | B12: =VLOOKUP($A12,Fixtures!$A$2:$H$49,2) -> Costa Rica | C12: =VLOOKUP($A12,Fixtures!$A$2:$H$49,3) -> Serbia | D12: =VLOOKUP($A12,Fixtures!$A$2:$H$49,6) -> 4.5 | E12: =VLOOKUP($A12,Fixtures!$A$2:$H$49,8) -> 1.91 | F12: =VLOOKUP($A12,Fixtures!$A$2:$H$49,7) -> 3.1 | G12: favourite | H12: =_xludf.IFS(I12=$D12,$B12,I12=$E12,$C12,I12=$F12,"Draw",I12="","") -> #NAME? | I12: =_xludf.IFS(G12="home",$D12,G12="away",$E12,G12="draw",$F12,G12="favourite",MIN($D12:$F12),G12="outsider",MAX($D12:$F12),G12="random",INDEX($D12:$F12,1,RANDBETWEEN(1,3)),G12="","") -> #NAME? | K12: outsider | L12: =_xludf.IFS(M12=$D12,$B12,M12=$E12,$C12,M12=$F12,"Draw",M12="","") -> #NAME? | M12: =_xludf.IFS(K12="home",$D12,K12="away",$E12,K12="draw",$F12,K12="favourite",MIN($D12:$F12),K12="outsider",MAX($D12:$F12),K12="random",INDEX($D12:$F12,1,RANDBETWEEN(1,3)),K12="","") -> #NAME? | O12: outsider | P12: =_xludf.IFS(Q12=$D12,$B12,Q12=$E12,$C12,Q12=$F12,"Draw",Q12="","") -> #NAME? | Q12: =_xludf.IFS(O12="home",$D12,O12="away",$E12,O12="draw",$F12,O12="favourite",MIN($D12:$F12),O12="outsider",MAX($D12:$F12),O12="random",INDEX($D12:$F12,1,RANDBETWEEN(1,3)),O12="","") -> #NAME? | S12: outsider | T12: =_xludf.IFS(U12=$D12,$B12,U12=$E12,$C12,U12=$F12,"Draw",U12="","") -> #NAME? | U12: =_xludf.IFS(S12="home",$D12,S12="away",$E12,S12="draw",$F12,S12="favourite",MIN($D12:$F12),S12="outsider",MAX($D12:$F12),S12="random",INDEX($D12:$F12,1,RANDBETWEEN(1,3)),S12="","") -> #NAME?
A13: 10 | B13: =VLOOKUP($A13,Fixtures!$A$2:$H$49,2) -> Germany | C13: =VLOOKUP($A13,Fixtures!$A$2:$H$49,3) -> Mexico | D13: =VLOOKUP($A13,Fixtures!$A$2:$H$49,6) -> 1.4 | E13: =VLOOKUP($A13,Fixtures!$A$2:$H$49,8) -> 7.5 | F13: =VLOOKUP($A13,Fixtures!$A$2:$H$49,7) -> 4.2 | G13: favourite | H13: =_xludf.IFS(I13=$D13,$B13,I13=$E13,$C13,I13=$F13,"Draw",I13="","") -> #NAME? | I13: =_xludf.IFS(G13="home",$D13,G13="away",$E13,G13="draw",$F13,G13="favourite",MIN($D13:$F13),G13="outsider",MAX($D13:$F13),G13="random",INDEX($D13:$F13,1,RANDBETWEEN(1,3)),G13="","") -> #NAME? | K13: outsider | L13: =_xludf.IFS(M13=$D13,$B13,M13=$E13,$C13,M13=$F13,"Draw",M13="","") -> #NAME? | M13: =_xludf.IFS(K13="home",$D13,K13="away",$E13,K13="draw",$F13,K13="favourite",MIN($D13:$F13),K13="outsider",MAX($D13:$F13),K13="random",INDEX($D13:$F13,1,RANDBETWEEN(1,3)),K13="","") -> #NAME? | O13: favourite | P13: =_xludf.IFS(Q13=$D13,$B13,Q13=$E13,$C13,Q13=$F13,"Draw",Q13="","") -> #NAME? | Q13: =_xludf.IFS(O13="home",$D13,O13="away",$E13,O13="draw",$F13,O13="favourite",MIN($D13:$F13),O13="outsider",MAX($D13:$F13),O13="random",INDEX($D13:$F13,1,RANDBETWEEN(1,3)),O13="","") -> #NAME? | S13: favourite | T13: =_xludf.IFS(U13=$D13,$B13,U13=$E13,$C13,U13=$F13,"Draw",U13="","") -> #NAME? | U13: =_xludf.IFS(S13="home",$D13,S13="away",$E13,S13="draw",$F13,S13="favourite",MIN($D13:$F13),S13="outsider",MAX($D13:$F13),S13="random",INDEX($D13:$F13,1,RANDBETWEEN(1,3)),S13="","") -> #NAME?
A14: 11 | B14: =VLOOKUP($A14,Fixtures!$A$2:$H$49,2) -> Brazil | C14: =VLOOKUP($A14,Fixtures!$A$2:$H$49,3) -> Switzerland | D14: =VLOOKUP($A14,Fixtures!$A$2:$H$49,6) -> 1.36 | E14: =VLOOKUP($A14,Fixtures!$A$2:$H$49,8) -> 8.5 | F14: =VLOOKUP($A14,Fixtures!$A$2:$H$49,7) -> 4.5 | G14: favourite | H14: =_xludf.IFS(I14=$D14,$B14,I14=$E14,$C14,I14=$F14,"Draw",I14="","") -> #NAME? | I14: =_xludf.IFS(G14="home",$D14,G14="away",$E14,G14="draw",$F14,G14="favourite",MIN($D14:$F14),G14="outsider",MAX($D14:$F14),G14="random",INDEX($D14:$F14,1,RANDBETWEEN(1,3)),G14="","") -> #NAME? | K14: outsider | L14: =_xludf.IFS(M14=$D14,$B14,M14=$E14,$C14,M14=$F14,"Draw",M14="","") -> #NAME? | M14: =_xludf.IFS(K14="home",$D14,K14="away",$E14,K14="draw",$F14,K14="favourite",MIN($D14:$F14),K14="outsider",MAX($D14:$F14),K14="random",INDEX($D14:$F14,1,RANDBETWEEN(1,3)),K14="","") -> #NAME? | O14: favourite | P14: =_xludf.IFS(Q14=$D14,$B14,Q14=$E14,$C14,Q14=$F14,"Draw",Q14="","") -> #NAME? | Q14: =_xludf.IFS(O14="home",$D14,O14="away",$E14,O14="draw",$F14,O14="favourite",MIN($D14:$F14),O14="outsider",MAX($D14:$F14),O14="random",INDEX($D14:$F14,1,RANDBETWEEN(1,3)),O14="","") -> #NAME? | S14: favourite | T14: =_xludf.IFS(U14=$D14,$B14,U14=$E14,$C14,U14=$F14,"Draw",U14="","") -> #NAME? | U14: =_xludf.IFS(S14="home",$D14,S14="away",$E14,S14="draw",$F14,S14="favourite",MIN($D14:$F14),S14="outsider",MAX($D14:$F14),S14="random",INDEX($D14:$F14,1,RANDBETWEEN(1,3)),S14="","") -> #NAME?
A15: 12 | B15: =VLOOKUP($A15,Fixtures!$A$2:$H$49,2) -> Sweden | C15: =VLOOKUP($A15,Fixtures!$A$2:$H$49,3) -> Korea Republic | D15: =VLOOKUP($A15,Fixtures!$A$2:$H$49,6) -> 2 | E15: =VLOOKUP($A15,Fixtures!$A$2:$H$49,8) -> 4 | F15: =VLOOKUP($A15,Fixtures!$A$2:$H$49,7) -> 3.1 | G15: favourite | H15: =_xludf.IFS(I15=$D15,$B15,I15=$E15,$C15,I15=$F15,"Draw",I15="","") -> #NAME? | I15: =_xludf.IFS(G15="home",$D15,G15="away",$E15,G15="draw",$F15,G15="favourite",MIN($D15:$F15),G15="outsider",MAX($D15:$F15),G15="random",INDEX($D15:$F15,1,RANDBETWEEN(1,3)),G15="","") -> #NAME? | K15: outsider | L15: =_xludf.IFS(M15=$D15,$B15,M15=$E15,$C15,M15=$F15,"Draw",M15="","") -> #NAME? | M15: =_xludf.IFS(K15="home",$D15,K15="away",$E15,K15="draw",$F15,K15="favourite",MIN($D15:$F15),K15="outsider",MAX($D15:$F15),K15="random",INDEX($D15:$F15,1,RANDBETWEEN(1,3)),K15="","") -> #NAME? | O15: favourite | P15: =_xludf.IFS(Q15=$D15,$B15,Q15=$E15,$C15,Q15=$F15,"Draw",Q15="","") -> #NAME? | Q15: =_xludf.IFS(O15="home",$D15,O15="away",$E15,O15="draw",$F15,O15="favourite",MIN($D15:$F15),O15="outsider",MAX($D15:$F15),O15="random",INDEX($D15:$F15,1,RANDBETWEEN(1,3)),O15="","") -> #NAME? | S15: outsider | T15: =_xludf.IFS(U15=$D15,$B15,U15=$E15,$C15,U15=$F15,"Draw",U15="","") -> #NAME? | U15: =_xludf.IFS(S15="home",$D15,S15="away",$E15,S15="draw",$F15,S15="favourite",MIN($D15:$F15),S15="outsider",MAX($D15:$F15),S15="random",INDEX($D15:$F15,1,RANDBETWEEN(1,3)),S15="","") -> #NAME?
... A19: 16 | B19: =VLOOKUP($A19,Fixtures!$A$2:$H$49,2) -> Poland | C19: =VLOOKUP($A19,Fixtures!$A$2:$H$49,3) -> Senegal | D19: =VLOOKUP($A19,Fixtures!$A$2:$H$49,6) -> 2.25 | E19: =VLOOKUP($A19,Fixtures!$A$2:$H$49,8) -> 3.3 | F19: =VLOOKUP($A19,Fixtures!$A$2:$H$49,7) -> 3.1 | G19: favourite | H19: =_xludf.IFS(I19=$D19,$B19,I19=$E19,$C19,I19=$F19,"Draw",I19="","") -> #NAME? | I19: =_xludf.IFS(G19="home",$D19,G19="away",$E19,G19="draw",$F19,G19="favourite",MIN($D19:$F19),G19="outsider",MAX($D19:$F19),G19="random",INDEX($D19:$F19,1,RANDBETWEEN(1,3)),G19="","") -> #NAME? | K19: outsider | L19: =_xludf.IFS(M19=$D19,$B19,M19=$E19,$C19,M19=$F19,"Draw",M19="","") -> #NAME? | M19: =_xludf.IFS(K19="home",$D19,K19="away",$E19,K19="draw",$F19,K19="favourite",MIN($D19:$F19),K19="outsider",MAX($D19:$F19),K19="random",INDEX($D19:$F19,1,RANDBETWEEN(1,3)),K19="","") -> #NAME? | O19: draw | P19: =_xludf.IFS(Q19=$D19,$B19,Q19=$E19,$C19,Q19=$F19,"Draw",Q19="","") -> #NAME? | Q19: =_xludf.IFS(O19="home",$D19,O19="away",$E19,O19="draw",$F19,O19="favourite",MIN($D19:$F19),O19="outsider",MAX($D19:$F19),O19="random",INDEX($D19:$F19,1,RANDBETWEEN(1,3)),O19="","") -> #NAME? | S19: outsider | T19: =_xludf.IFS(U19=$D19,$B19,U19=$E19,$C19,U19=$F19,"Draw",U19="","") -> #NAME? | U19: =_xludf.IFS(S19="home",$D19,S19="away",$E19,S19="draw",$F19,S19="favourite",MIN($D19:$F19),S19="outsider",MAX($D19:$F19),S19="random",INDEX($D19:$F19,1,RANDBETWEEN(1,3)),S19="","") -> #NAME?
A21: Round 1 | G21: Total Odds | J21: =IF(COUNTIF(J4:J19,"=L") > 0,0,"") | K21: Total Odds | N21: =IF(COUNTIF(N4:N19,"=L") > 0,0,"") | O21: Total Odds | R21: =IF(COUNTIF(R4:R19,"=L") > 0,0,"") | S21: Total Odds | V21: =IF(COUNTIF(V4:V19,"=L") > 0,0,"")
A22: Total Stake | G22: =PRODUCT(I4:I19) -> #NAME? | K22: =PRODUCT(M4:M19) -> #NAME? | O22: =PRODUCT(Q4:Q19) -> #NAME? | S22: =PRODUCT(U4:U19) -> #NAME?
A23: =SUM(G25:AA25) -> 4
G24: Stake | K24: Stake | O24: Stake | S24: Stake
G25: 1 | K25: 1 | O25: 1 | S25: 1
G27: Payout | K27: Payout | O27: Payout | S27: Payout
G28: =G25*G22 -> #NAME? | K28: =K25*K22 -> #NAME? | O28: =O25*O22 -> #NAME? | S28: =S25*S22 -> #NAME?

Sheet BetTracker
A1: Total Stake | B1: =SUM(B7:B1102) -> 16
A2: Winnings | B2: =SUM(I7:I1300) -> #NAME?
A3: P/L | B3: =B2-B1 -> #NAME?
A4: ROI | B4: =B3/B1 -> #NAME?
A6: bet_id | B6: stake | C6: num_bets | D6: expected_odds | E6: actual_odds | F6: num_win | G6: num_lose | H6: expected_payout | I6: actual_payout | J6: result
A7: 1 | B7: 10 | C7: =IF(COUNTIF(BetTrackerLines!$A$2:$A$1096,A7)=0,"",COUNTIF(BetTrackerLines!$A$2:$A$1096,A7)) -> 10 | D7: {=PRODUCT(IF(BetTrackerLines!$A$2:$A$1700=A7,BetTrackerLines!$K$2:$K$1000))} -> #NAME? | F7: =COUNTIFS(BetTrackerLines!$A$2:$A$1000,$A7,BetTrackerLines!$L$2:$L$1000,"win") -> 0 | G7: =COUNTIFS(BetTrackerLines!$A$2:$A$1000,$A7,BetTrackerLines!$L$2:$L$1000,"lose") -> 0 | H7: =IF(D7="","",IF(B7="","",D7*B7)) -> #NAME? | I7: =_xludf.IFS(E7="","",B7="","",G7>0,0,E7<>""&B7<>"",E7*B7) -> #NAME? | J7: =_xludf.IFS(F7="","",G7="","",F7+G7<C7,"",F7=C7,"win",G7>0,"lose") -> #NAME?
A8: 2 | B8: 1 | C8: =IF(COUNTIF(BetTrackerLines!$A$2:$A$1096,A8)=0,"",COUNTIF(BetTrackerLines!$A$2:$A$1096,A8)) -> 10 | D8: {=PRODUCT(IF(BetTrackerLines!$A$2:$A$1700=A8,BetTrackerLines!$K$2:$K$1000))} -> #NAME? | F8: =COUNTIFS(BetTrackerLines!$A$2:$A$1000,$A8,BetTrackerLines!$L$2:$L$1000,"win") -> 0 | G8: =COUNTIFS(BetTrackerLines!$A$2:$A$1000,$A8,BetTrackerLines!$L$2:$L$1000,"lose") -> 0 | H8: =IF(D8="","",IF(B8="","",D8*B8)) -> #NAME? | I8: =_xludf.IFS(E8="","",B8="","",G8>0,0,E8<>""&B8<>"",E8*B8) -> #NAME? | J8: =_xludf.IFS(F8="","",G8="","",F8+G8<C8,"",F8=C8,"win",G8>0,"lose") -> #NAME?
A9: 3 | B9: 1 | C9: =IF(COUNTIF(BetTrackerLines!$A$2:$A$1096,A9)=0,"",COUNTIF(BetTrackerLines!$A$2:$A$1096,A9)) -> 10 | D9: {=PRODUCT(IF(BetTrackerLines!$A$2:$A$1700=A9,BetTrackerLines!$K$2:$K$1000))} -> 110059.19 | F9: =COUNTIFS(BetTrackerLines!$A$2:$A$1000,$A9,BetTrackerLines!$L$2:$L$1000,"win") -> 0 | G9: =COUNTIFS(BetTrackerLines!$A$2:$A$1000,$A9,BetTrackerLines!$L$2:$L$1000,"lose") -> 0 | H9: =IF(D9="","",IF(B9="","",D9*B9)) -> 110059.19 | I9: =_xludf.IFS(E9="","",B9="","",G9>0,0,E9<>""&B9<>"",E9*B9) -> #NAME? | J9: =_xludf.IFS(F9="","",G9="","",F9+G9<C9,"",F9=C9,"win",G9>0,"lose") -> #NAME?
A10: 4 | B10: 1 | C10: =IF(COUNTIF(BetTrackerLines!$A$2:$A$1096,A10)=0,"",COUNTIF(BetTrackerLines!$A$2:$A$1096,A10)) -> 10 | D10: {=PRODUCT(IF(BetTrackerLines!$A$2:$A$1700=A10,BetTrackerLines!$K$2:$K$1000))} -> #NAME? | F10: =COUNTIFS(BetTrackerLines!$A$2:$A$1000,$A10,BetTrackerLines!$L$2:$L$1000,"win") -> 0 | G10: =COUNTIFS(BetTrackerLines!$A$2:$A$1000,$A10,BetTrackerLines!$L$2:$L$1000,"lose") -> 0 | H10: =IF(D10="","",IF(B10="","",D10*B10)) -> #NAME? | I10: =_xludf.IFS(E10="","",B10="","",G10>0,0,E10<>""&B10<>"",E10*B10) -> #NAME? | J10: =_xludf.IFS(F10="","",G10="","",F10+G10<C10,"",F10=C10,"win",G10>0,"lose") -> #NAME?
A11: 5 | B11: 1 | C11: =IF(COUNTIF(BetTrackerLines!$A$2:$A$1096,A11)=0,"",COUNTIF(BetTrackerLines!$A$2:$A$1096,A11)) | D11: {=PRODUCT(IF(BetTrackerLines!$A$2:$A$1700=A11,BetTrackerLines!$K$2:$K$1000))} -> 0 | F11: =COUNTIFS(BetTrackerLines!$A$2:$A$1000,$A11,BetTrackerLines!$L$2:$L$1000,"win") -> 0 | G11: =COUNTIFS(BetTrackerLines!$A$2:$A$1000,$A11,BetTrackerLines!$L$2:$L$1000,"lose") -> 0 | H11: =IF(D11="","",IF(B11="","",D11*B11)) -> 0 | I11: =_xludf.IFS(E11="","",B11="","",G11>0,0,E11<>""&B11<>"",E11*B11) -> #NAME? | J11: =_xludf.IFS(F11="","",G11="","",F11+G11<C11,"",F11=C11,"win",G11>0,"lose") -> #NAME?
A12: 6 | B12: 1 | C12: =IF(COUNTIF(BetTrackerLines!$A$2:$A$1096,A12)=0,"",COUNTIF(BetTrackerLines!$A$2:$A$1096,A12)) | D12: {=PRODUCT(IF(BetTrackerLines!$A$2:$A$1700=A12,BetTrackerLines!$K$2:$K$1000))} -> 0 | F12: =COUNTIFS(BetTrackerLines!$A$2:$A$1000,$A12,BetTrackerLines!$L$2:$L$1000,"win") -> 0 | G12: =COUNTIFS(BetTrackerLines!$A$2:$A$1000,$A12,BetTrackerLines!$L$2:$L$1000,"lose") -> 0 | H12: =IF(D12="","",IF(B12="","",D12*B12)) -> 0 | I12: =_xludf.IFS(E12="","",B12="","",G12>0,0,E12<>""&B12<>"",E12*B12) -> #NAME? | J12: =_xludf.IFS(F12="","",G12="","",F12+G12<C12,"",F12=C12,"win",G12>0,"lose") -> #NAME?
A13: 7 | B13: 1 | C13: =IF(COUNTIF(BetTrackerLines!$A$2:$A$1096,A13)=0,"",COUNTIF(BetTrackerLines!$A$2:$A$1096,A13)) | D13: {=PRODUCT(IF(BetTrackerLines!$A$2:$A$1700=A13,BetTrackerLines!$K$2:$K$1000))} -> 0 | F13: =COUNTIFS(BetTrackerLines!$A$2:$A$1000,$A13,BetTrackerLines!$L$2:$L$1000,"win") -> 0 | G13: =COUNTIFS(BetTrackerLines!$A$2:$A$1000,$A13,BetTrackerLines!$L$2:$L$1000,"lose") -> 0 | H13: =IF(D13="","",IF(B13="","",D13*B13)) -> 0 | I13: =_xludf.IFS(E13="","",B13="","",G13>0,0,E13<>""&B13<>"",E13*B13) -> #NAME? | J13: =_xludf.IFS(F13="","",G13="","",F13+G13<C13,"",F13=C13,"win",G13>0,"lose") -> #NAME?

Sheet BetTrackerLines
A1: bet_id | B1: fixture_id | C1: round | D1: home_team | E1: away_team | F1: home_team_odds | G1: away_team_odds | H1: draw_odds | I1: prediction_type | J1: prediction_selection | K1: prediction_odds | L1: result
A2: 1 | B2: 1 | C2: =VLOOKUP($B2,Fixtures!$A$2:$H$49,4) -> 1 | D2: =VLOOKUP($B2,Fixtures!$A$2:$H$49,2) -> Russia | E2: =VLOOKUP($B2,Fixtures!$A$2:$H$49,3) -> Saudi Arabia | F2: =VLOOKUP($B2,Fixtures!$A$2:$H$49,6) -> 1.4 | G2: =VLOOKUP($B2,Fixtures!$A$2:$H$49,8) -> 9 | H2: =VLOOKUP($B2,Fixtures!$A$2:$H$49,7) -> 4 | I2: favourite | J2: =_xludf.IFS(K2=F2,D2,K2=G2,E2,K2=H2,"Draw",K2="","") -> #NAME? | K2: =_xludf.IFS(I2="home",F2,I2="away",G2,I2="draw",H2,I2="favourite",MIN(F2:H2),I2="outsider",MAX(F2:H2),I2="random",INDEX(F2:H2,1,RANDBETWEEN(1,3)),I2="","") -> #NAME?
A3: 1 | B3: 2 | C3: =VLOOKUP($B3,Fixtures!$A$2:$H$49,4) -> 1 | D3: =VLOOKUP($B3,Fixtures!$A$2:$H$49,2) -> Egypt | E3: =VLOOKUP($B3,Fixtures!$A$2:$H$49,3) -> Uruguay | F3: =VLOOKUP($B3,Fixtures!$A$2:$H$49,6) -> 7 | G3: =VLOOKUP($B3,Fixtures!$A$2:$H$49,8) -> 1.57 | H3: =VLOOKUP($B3,Fixtures!$A$2:$H$49,7) -> 3.5 | I3: favourite | J3: =_xludf.IFS(K3=F3,D3,K3=G3,E3,K3=H3,"Draw",K3="","") -> #NAME? | K3: =_xludf.IFS(I3="home",F3,I3="away",G3,I3="draw",H3,I3="favourite",MIN(F3:H3),I3="outsider",MAX(F3:H3),I3="random",INDEX(F3:H3,1,RANDBETWEEN(1,3)),I3="","") -> #NAME?
A4: 1 | B4: 3 | C4: =VLOOKUP($B4,Fixtures!$A$2:$H$49,4) -> 1 | D4: =VLOOKUP($B4,Fixtures!$A$2:$H$49,2) -> Morocco | E4: =VLOOKUP($B4,Fixtures!$A$2:$H$49,3) -> Iran | F4: =VLOOKUP($B4,Fixtures!$A$2:$H$49,6) -> 2.25 | G4: =VLOOKUP($B4,Fixtures!$A$2:$H$49,8) -> 3.75 | H4: =VLOOKUP($B4,Fixtures!$A$2:$H$49,7) -> 2.88 | I4: favourite | J4: =_xludf.IFS(K4=F4,D4,K4=G4,E4,K4=H4,"Draw",K4="","") -> #NAME? | K4: =_xludf.IFS(I4="home",F4,I4="away",G4,I4="draw",H4,I4="favourite",MIN(F4:H4),I4="outsider",MAX(F4:H4),I4="random",INDEX(F4:H4,1,RANDBETWEEN(1,3)),I4="","") -> #NAME?
A5: 1 | B5: 4 | C5: =VLOOKUP($B5,Fixtures!$A$2:$H$49,4) -> 1 | D5: =VLOOKUP($B5,Fixtures!$A$2:$H$49,2) -> Portugal | E5: =VLOOKUP($B5,Fixtures!$A$2:$H$49,3) -> Spain | F5: =VLOOKUP($B5,Fixtures!$A$2:$H$49,6) -> 4.33 | G5: =VLOOKUP($B5,Fixtures!$A$2:$H$49,8) -> 1.91 | H5: =VLOOKUP($B5,Fixtures!$A$2:$H$49,7) -> 3.25 | I5: favourite | J5: =_xludf.IFS(K5=F5,D5,K5=G5,E5,K5=H5,"Draw",K5="","") -> #NAME? | K5: =_xludf.IFS(I5="home",F5,I5="away",G5,I5="draw",H5,I5="favourite",MIN(F5:H5),I5="outsider",MAX(F5:H5),I5="random",INDEX(F5:H5,1,RANDBETWEEN(1,3)),I5="","") -> #NAME?
A6: 1 | B6: 5 | C6: =VLOOKUP($B6,Fixtures!$A$2:$H$49,4) -> 1 | D6: =VLOOKUP($B6,Fixtures!$A$2:$H$49,2) -> France | E6: =VLOOKUP($B6,Fixtures!$A$2:$H$49,3) -> Australia | F6: =VLOOKUP($B6,Fixtures!$A$2:$H$49,6) -> 1.2 | G6: =VLOOKUP($B6,Fixtures!$A$2:$H$49,8) -> 14 | H6: =VLOOKUP($B6,Fixtures!$A$2:$H$49,7) -> 6 | I6: favourite | J6: =_xludf.IFS(K6=F6,D6,K6=G6,E6,K6=H6,"Draw",K6="","") -> #NAME? | K6: =_xludf.IFS(I6="home",F6,I6="away",G6,I6="draw",H6,I6="favourite",MIN(F6:H6),I6="outsider",MAX(F6:H6),I6="random",INDEX(F6:H6,1,RANDBETWEEN(1,3)),I6="","") -> #NAME?
A7: 1 | B7: 6 | C7: =VLOOKUP($B7,Fixtures!$A$2:$H$49,4) -> 1 | D7: =VLOOKUP($B7,Fixtures!$A$2:$H$49,2) -> Argentina | E7: =VLOOKUP($B7,Fixtures!$A$2:$H$49,3) -> Iceland | F7: =VLOOKUP($B7,Fixtures!$A$2:$H$49,6) -> 1.28 | G7: =VLOOKUP($B7,Fixtures!$A$2:$H$49,8) -> 13 | H7: =VLOOKUP($B7,Fixtures!$A$2:$H$49,7) -> 4.5 | I7: favourite | J7: =_xludf.IFS(K7=F7,D7,K7=G7,E7,K7=H7,"Draw",K7="","") -> #NAME? | K7: =_xludf.IFS(I7="home",F7,I7="away",G7,I7="draw",H7,I7="favourite",MIN(F7:H7),I7="outsider",MAX(F7:H7),I7="random",INDEX(F7:H7,1,RANDBETWEEN(1,3)),I7="","") -> #NAME?
A8: 1 | B8: 7 | C8: =VLOOKUP($B8,Fixtures!$A$2:$H$49,4) -> 1 | D8: =VLOOKUP($B8,Fixtures!$A$2:$H$49,2) -> Peru | E8: =VLOOKUP($B8,Fixtures!$A$2:$H$49,3) -> Denmark | F8: =VLOOKUP($B8,Fixtures!$A$2:$H$49,6) -> 3.1 | G8: =VLOOKUP($B8,Fixtures!$A$2:$H$49,8) -> 2.37 | H8: =VLOOKUP($B8,Fixtures!$A$2:$H$49,7) -> 3.1 | I8: favourite | J8: =_xludf.IFS(K8=F8,D8,K8=G8,E8,K8=H8,"Draw",K8="","") -> #NAME? | K8: =_xludf.IFS(I8="home",F8,I8="away",G8,I8="draw",H8,I8="favourite",MIN(F8:H8),I8="outsider",MAX(F8:H8),I8="random",INDEX(F8:H8,1,RANDBETWEEN(1,3)),I8="","") -> #NAME?
A9: 1 | B9: 8 | C9: =VLOOKUP($B9,Fixtures!$A$2:$H$49,4) -> 1 | D9: =VLOOKUP($B9,Fixtures!$A$2:$H$49,2) -> Croatia | E9: =VLOOKUP($B9,Fixtures!$A$2:$H$49,3) -> Nigeria | F9: =VLOOKUP($B9,Fixtures!$A$2:$H$49,6) -> 1.67 | G9: =VLOOKUP($B9,Fixtures!$A$2:$H$49,8) -> 5.5 | H9: =VLOOKUP($B9,Fixtures!$A$2:$H$49,7) -> 3.5 | I9: favourite | J9: =_xludf.IFS(K9=F9,D9,K9=G9,E9,K9=H9,"Draw",K9="","") -> #NAME? | K9: =_xludf.IFS(I9="home",F9,I9="away",G9,I9="draw",H9,I9="favourite",MIN(F9:H9),I9="outsider",MAX(F9:H9),I9="random",INDEX(F9:H9,1,RANDBETWEEN(1,3)),I9="","") -> #NAME?
A10: 1 | B10: 9 | C10: =VLOOKUP($B10,Fixtures!$A$2:$H$49,4) -> 1 | D10: =VLOOKUP($B10,Fixtures!$A$2:$H$49,2) -> Costa Rica | E10: =VLOOKUP($B10,Fixtures!$A$2:$H$49,3) -> Serbia | F10: =VLOOKUP($B10,Fixtures!$A$2:$H$49,6) -> 4.5 | G10: =VLOOKUP($B10,Fixtures!$A$2:$H$49,8) -> 1.91 | H10: =VLOOKUP($B10,Fixtures!$A$2:$H$49,7) -> 3.1 | I10: favourite | J10: =_xludf.IFS(K10=F10,D10,K10=G10,E10,K10=H10,"Draw",K10="","") -> #NAME? | K10: =_xludf.IFS(I10="home",F10,I10="away",G10,I10="draw",H10,I10="favourite",MIN(F10:H10),I10="outsider",MAX(F10:H10),I10="random",INDEX(F10:H10,1,RANDBETWEEN(1,3)),I10="","") -> #NAME?
A11: 1 | B11: 10 | C11: =VLOOKUP($B11,Fixtures!$A$2:$H$49,4) -> 1 | D11: =VLOOKUP($B11,Fixtures!$A$2:$H$49,2) -> Germany | E11: =VLOOKUP($B11,Fixtures!$A$2:$H$49,3) -> Mexico | F11: =VLOOKUP($B11,Fixtures!$A$2:$H$49,6) -> 1.4 | G11: =VLOOKUP($B11,Fixtures!$A$2:$H$49,8) -> 7.5 | H11: =VLOOKUP($B11,Fixtures!$A$2:$H$49,7) -> 4.2 | I11: favourite | J11: =_xludf.IFS(K11=F11,D11,K11=G11,E11,K11=H11,"Draw",K11="","") -> #NAME? | K11: =_xludf.IFS(I11="home",F11,I11="away",G11,I11="draw",H11,I11="favourite",MIN(F11:H11),I11="outsider",MAX(F11:H11),I11="random",INDEX(F11:H11,1,RANDBETWEEN(1,3)),I11="","") -> #NAME?
A12: 2 | B12: 1 | C12: =VLOOKUP($B12,Fixtures!$A$2:$H$49,4) -> 1 | D12: =VLOOKUP($B12,Fixtures!$A$2:$H$49,2) -> Russia | E12: =VLOOKUP($B12,Fixtures!$A$2:$H$49,3) -> Saudi Arabia | F12: =VLOOKUP($B12,Fixtures!$A$2:$H$49,6) -> 1.4 | G12: =VLOOKUP($B12,Fixtures!$A$2:$H$49,8) -> 9 | H12: =VLOOKUP($B12,Fixtures!$A$2:$H$49,7) -> 4 | I12: outsider | J12: =_xludf.IFS(K12=F12,D12,K12=G12,E12,K12=H12,"Draw",K12="","") -> #NAME? | K12: =_xludf.IFS(I12="home",F12,I12="away",G12,I12="draw",H12,I12="favourite",MIN(F12:H12),I12="outsider",MAX(F12:H12),I12="random",INDEX(F12:H12,1,RANDBETWEEN(1,3)),I12="","") -> #NAME?
A13: 2 | B13: 2 | C13: =VLOOKUP($B13,Fixtures!$A$2:$H$49,4) -> 1 | D13: =VLOOKUP($B13,Fixtures!$A$2:$H$49,2) -> Egypt | E13: =VLOOKUP($B13,Fixtures!$A$2:$H$49,3) -> Uruguay | F13: =VLOOKUP($B13,Fixtures!$A$2:$H$49,6) -> 7 | G13: =VLOOKUP($B13,Fixtures!$A$2:$H$49,8) -> 1.57 | H13: =VLOOKUP($B13,Fixtures!$A$2:$H$49,7) -> 3.5 | I13: outsider | J13: =_xludf.IFS(K13=F13,D13,K13=G13,E13,K13=H13,"Draw",K13="","") -> #NAME? | K13: =_xludf.IFS(I13="home",F13,I13="away",G13,I13="draw",H13,I13="favourite",MIN(F13:H13),I13="outsider",MAX(F13:H13),I13="random",INDEX(F13:H13,1,RANDBETWEEN(1,3)),I13="","") -> #NAME?
... A21: 2 | B21: 10 | C21: =VLOOKUP($B21,Fixtures!$A$2:$H$49,4) -> 1 | D21: =VLOOKUP($B21,Fixtures!$A$2:$H$49,2) -> Germany | E21: =VLOOKUP($B21,Fixtures!$A$2:$H$49,3) -> Mexico | F21: =VLOOKUP($B21,Fixtures!$A$2:$H$49,6) -> 1.4 | G21: =VLOOKUP($B21,Fixtures!$A$2:$H$49,8) -> 7.5 | H21: =VLOOKUP($B21,Fixtures!$A$2:$H$49,7) -> 4.2 | I21: outsider | J21: =_xludf.IFS(K21=F21,D21,K21=G21,E21,K21=H21,"Draw",K21="","") -> #NAME? | K21: =_xludf.IFS(I21="home",F21,I21="away",G21,I21="draw",H21,I21="favourite",MIN(F21:H21),I21="outsider",MAX(F21:H21),I21="random",INDEX(F21:H21,1,RANDBETWEEN(1,3)),I21="","") -> #NAME?
A22: 3 | B22: 1 | C22: =VLOOKUP($B22,Fixtures!$A$2:$H$49,4) -> 1 | D22: =VLOOKUP($B22,Fixtures!$A$2:$H$49,2) -> Russia | E22: =VLOOKUP($B22,Fixtures!$A$2:$H$49,3) -> Saudi Arabia | F22: =VLOOKUP($B22,Fixtures!$A$2:$H$49,6) -> 1.4 | G22: =VLOOKUP($B22,Fixtures!$A$2:$H$49,8) -> 9 | H22: =VLOOKUP($B22,Fixtures!$A$2:$H$49,7) -> 4 | I22: random | J22: Draw | K22: 4.5
A23: 3 | B23: 2 | C23: =VLOOKUP($B23,Fixtures!$A$2:$H$49,4) -> 1 | D23: =VLOOKUP($B23,Fixtures!$A$2:$H$49,2) -> Egypt | E23: =VLOOKUP($B23,Fixtures!$A$2:$H$49,3) -> Uruguay | F23: =VLOOKUP($B23,Fixtures!$A$2:$H$49,6) -> 7 | G23: =VLOOKUP($B23,Fixtures!$A$2:$H$49,8) -> 1.57 | H23: =VLOOKUP($B23,Fixtures!$A$2:$H$49,7) -> 3.5 | I23: random | J23: Egypt | K23: 4.5
A24: 3 | B24: 3 | C24: =VLOOKUP($B24,Fixtures!$A$2:$H$49,4) -> 1 | D24: =VLOOKUP($B24,Fixtures!$A$2:$H$49,2) -> Morocco | E24: =VLOOKUP($B24,Fixtures!$A$2:$H$49,3) -> Iran | F24: =VLOOKUP($B24,Fixtures!$A$2:$H$49,6) -> 2.25 | G24: =VLOOKUP($B24,Fixtures!$A$2:$H$49,8) -> 3.75 | H24: =VLOOKUP($B24,Fixtures!$A$2:$H$49,7) -> 2.88 | I24: random | J24: Morocco | K24: 2.1
A25: 3 | B25: 4 | C25: =VLOOKUP($B25,Fixtures!$A$2:$H$49,4) -> 1 | D25: =VLOOKUP($B25,Fixtures!$A$2:$H$49,2) -> Portugal | E25: =VLOOKUP($B25,Fixtures!$A$2:$H$49,3) -> Spain | F25: =VLOOKUP($B25,Fixtures!$A$2:$H$49,6) -> 4.33 | G25: =VLOOKUP($B25,Fixtures!$A$2:$H$49,8) -> 1.91 | H25: =VLOOKUP($B25,Fixtures!$A$2:$H$49,7) -> 3.25 | I25: random | J25: Draw | K25: 3.3
A26: 3 | B26: 5 | C26: =VLOOKUP($B26,Fixtures!$A$2:$H$49,4) -> 1 | D26: =VLOOKUP($B26,Fixtures!$A$2:$H$49,2) -> France | E26: =VLOOKUP($B26,Fixtures!$A$2:$H$49,3) -> Australia | F26: =VLOOKUP($B26,Fixtures!$A$2:$H$49,6) -> 1.2 | G26: =VLOOKUP($B26,Fixtures!$A$2:$H$49,8) -> 14 | H26: =VLOOKUP($B26,Fixtures!$A$2:$H$49,7) -> 6 | I26: random | J26: Australia | K26: 15
A27: 3 | B27: 6 | C27: =VLOOKUP($B27,Fixtures!$A$2:$H$49,4) -> 1 | D27: =VLOOKUP($B27,Fixtures!$A$2:$H$49,2) -> Argentina | E27: =VLOOKUP($B27,Fixtures!$A$2:$H$49,3) -> Iceland | F27: =VLOOKUP($B27,Fixtures!$A$2:$H$49,6) -> 1.28 | G27: =VLOOKUP($B27,Fixtures!$A$2:$H$49,8) -> 13 | H27: =VLOOKUP($B27,Fixtures!$A$2:$H$49,7) -> 4.5 | I27: random | J27: Argentina | K27: 1.3
A28: 3 | B28: 7 | C28: =VLOOKUP($B28,Fixtures!$A$2:$H$49,4) -> 1 | D28: =VLOOKUP($B28,Fixtures!$A$2:$H$49,2) -> Peru | E28: =VLOOKUP($B28,Fixtures!$A$2:$H$49,3) -> Denmark | F28: =VLOOKUP($B28,Fixtures!$A$2:$H$49,6) -> 3.1 | G28: =VLOOKUP($B28,Fixtures!$A$2:$H$49,8) -> 2.37 | H28: =VLOOKUP($B28,Fixtures!$A$2:$H$49,7) -> 3.1 | I28: random | J28: Denmark | K28: 2.1
A29: 3 | B29: 8 | C29: =VLOOKUP($B29,Fixtures!$A$2:$H$49,4) -> 1 | D29: =VLOOKUP($B29,Fixtures!$A$2:$H$49,2) -> Croatia | E29: =VLOOKUP($B29,Fixtures!$A$2:$H$49,3) -> Nigeria | F29: =VLOOKUP($B29,Fixtures!$A$2:$H$49,6) -> 1.67 | G29: =VLOOKUP($B29,Fixtures!$A$2:$H$49,8) -> 5.5 | H29: =VLOOKUP($B29,Fixtures!$A$2:$H$49,7) -> 3.5 | I29: random | J29: Nigeria | K29: 4
A30: 3 | B30: 9 | C30: =VLOOKUP($B30,Fixtures!$A$2:$H$49,4) -> 1 | D30: =VLOOKUP($B30,Fixtures!$A$2:$H$49,2) -> Costa Rica | E30: =VLOOKUP($B30,Fixtures!$A$2:$H$49,3) -> Serbia | F30: =VLOOKUP($B30,Fixtures!$A$2:$H$49,6) -> 4.5 | G30: =VLOOKUP($B30,Fixtures!$A$2:$H$49,8) -> 1.91 | H30: =VLOOKUP($B30,Fixtures!$A$2:$H$49,7) -> 3.1 | I30: random | J30: Costa Rica | K30: 3.6
A31: 3 | B31: 10 | C31: =VLOOKUP($B31,Fixtures!$A$2:$H$49,4) -> 1 | D31: =VLOOKUP($B31,Fixtures!$A$2:$H$49,2) -> Germany | E31: =VLOOKUP($B31,Fixtures!$A$2:$H$49,3) -> Mexico | F31: =VLOOKUP($B31,Fixtures!$A$2:$H$49,6) -> 1.4 | G31: =VLOOKUP($B31,Fixtures!$A$2:$H$49,8) -> 7.5 | H31: =VLOOKUP($B31,Fixtures!$A$2:$H$49,7) -> 4.2 | I31: random | J31: Germany | K31: 1.33
A32: 4 | B32: 1 | C32: =VLOOKUP($B32,Fixtures!$A$2:$H$49,4) -> 1 | D32: =VLOOKUP($B32,Fixtures!$A$2:$H$49,2) -> Russia | E32: =VLOOKUP($B32,Fixtures!$A$2:$H$49,3) -> Saudi Arabia | F32: =VLOOKUP($B32,Fixtures!$A$2:$H$49,6) -> 1.4 | G32: =VLOOKUP($B32,Fixtures!$A$2:$H$49,8) -> 9 | H32: =VLOOKUP($B32,Fixtures!$A$2:$H$49,7) -> 4 | I32: away | J32: =_xludf.IFS(K32=F32,D32,K32=G32,E32,K32=H32,"Draw",K32="","") -> #NAME? | K32: =_xludf.IFS(I32="home",F32,I32="away",G32,I32="draw",H32,I32="favourite",MIN(F32:H32),I32="outsider",MAX(F32:H32),I32="random",INDEX(F32:H32,1,RANDBETWEEN(1,3)),I32="","") -> #NAME?
A33: 4 | B33: 2 | C33: =VLOOKUP($B33,Fixtures!$A$2:$H$49,4) -> 1 | D33: =VLOOKUP($B33,Fixtures!$A$2:$H$49,2) -> Egypt | E33: =VLOOKUP($B33,Fixtures!$A$2:$H$49,3) -> Uruguay | F33: =VLOOKUP($B33,Fixtures!$A$2:$H$49,6) -> 7 | G33: =VLOOKUP($B33,Fixtures!$A$2:$H$49,8) -> 1.57 | H33: =VLOOKUP($B33,Fixtures!$A$2:$H$49,7) -> 3.5 | I33: favourite | J33: =_xludf.IFS(K33=F33,D33,K33=G33,E33,K33=H33,"Draw",K33="","") -> #NAME? | K33: =_xludf.IFS(I33="home",F33,I33="away",G33,I33="draw",H33,I33="favourite",MIN(F33:H33),I33="outsider",MAX(F33:H33),I33="random",INDEX(F33:H33,1,RANDBETWEEN(1,3)),I33="","") -> #NAME?
A34: 4 | B34: 3 | C34: =VLOOKUP($B34,Fixtures!$A$2:$H$49,4) -> 1 | D34: =VLOOKUP($B34,Fixtures!$A$2:$H$49,2) -> Morocco | E34: =VLOOKUP($B34,Fixtures!$A$2:$H$49,3) -> Iran | F34: =VLOOKUP($B34,Fixtures!$A$2:$H$49,6) -> 2.25 | G34: =VLOOKUP($B34,Fixtures!$A$2:$H$49,8) -> 3.75 | H34: =VLOOKUP($B34,Fixtures!$A$2:$H$49,7) -> 2.88 | I34: favourite | J34: =_xludf.IFS(K34=F34,D34,K34=G34,E34,K34=H34,"Draw",K34="","") -> #NAME? | K34: =_xludf.IFS(I34="home",F34,I34="away",G34,I34="draw",H34,I34="favourite",MIN(F34:H34),I34="outsider",MAX(F34:H34),I34="random",INDEX(F34:H34,1,RANDBETWEEN(1,3)),I34="","") -> #NAME?
A35: 4 | B35: 4 | C35: =VLOOKUP($B35,Fixtures!$A$2:$H$49,4) -> 1 | D35: =VLOOKUP($B35,Fixtures!$A$2:$H$49,2) -> Portugal | E35: =VLOOKUP($B35,Fixtures!$A$2:$H$49,3) -> Spain | F35: =VLOOKUP($B35,Fixtures!$A$2:$H$49,6) -> 4.33 | G35: =VLOOKUP($B35,Fixtures!$A$2:$H$49,8) -> 1.91 | H35: =VLOOKUP($B35,Fixtures!$A$2:$H$49,7) -> 3.25 | I35: home | J35: =_xludf.IFS(K35=F35,D35,K35=G35,E35,K35=H35,"Draw",K35="","") -> #NAME? | K35: =_xludf.IFS(I35="home",F35,I35="away",G35,I35="draw",H35,I35="favourite",MIN(F35:H35),I35="outsider",MAX(F35:H35),I35="random",INDEX(F35:H35,1,RANDBETWEEN(1,3)),I35="","") -> #NAME?
A36: 4 | B36: 5 | C36: =VLOOKUP($B36,Fixtures!$A$2:$H$49,4) -> 1 | D36: =VLOOKUP($B36,Fixtures!$A$2:$H$49,2) -> France | E36: =VLOOKUP($B36,Fixtures!$A$2:$H$49,3) -> Australia | F36: =VLOOKUP($B36,Fixtures!$A$2:$H$49,6) -> 1.2 | G36: =VLOOKUP($B36,Fixtures!$A$2:$H$49,8) -> 14 | H36: =VLOOKUP($B36,Fixtures!$A$2:$H$49,7) -> 6 | I36: away | J36: =_xludf.IFS(K36=F36,D36,K36=G36,E36,K36=H36,"Draw",K36="","") -> #NAME? | K36: =_xludf.IFS(I36="home",F36,I36="away",G36,I36="draw",H36,I36="favourite",MIN(F36:H36),I36="outsider",MAX(F36:H36),I36="random",INDEX(F36:H36,1,RANDBETWEEN(1,3)),I36="","") -> #NAME?
A37: 4 | B37: 6 | C37: =VLOOKUP($B37,Fixtures!$A$2:$H$49,4) -> 1 | D37: =VLOOKUP($B37,Fixtures!$A$2:$H$49,2) -> Argentina | E37: =VLOOKUP($B37,Fixtures!$A$2:$H$49,3) -> Iceland | F37: =VLOOKUP($B37,Fixtures!$A$2:$H$49,6) -> 1.28 | G37: =VLOOKUP($B37,Fixtures!$A$2:$H$49,8) -> 13 | H37: =VLOOKUP($B37,Fixtures!$A$2:$H$49,7) -> 4.5 | I37: home | J37: =_xludf.IFS(K37=F37,D37,K37=G37,E37,K37=H37,"Draw",K37="","") -> #NAME? | K37: =_xludf.IFS(I37="home",F37,I37="away",G37,I37="draw",H37,I37="favourite",MIN(F37:H37),I37="outsider",MAX(F37:H37),I37="random",INDEX(F37:H37,1,RANDBETWEEN(1,3)),I37="","") -> #NAME?
A38: 4 | B38: 7 | C38: =VLOOKUP($B38,Fixtures!$A$2:$H$49,4) -> 1 | D38: =VLOOKUP($B38,Fixtures!$A$2:$H$49,2) -> Peru | E38: =VLOOKUP($B38,Fixtures!$A$2:$H$49,3) -> Denmark | F38: =VLOOKUP($B38,Fixtures!$A$2:$H$49,6) -> 3.1 | G38: =VLOOKUP($B38,Fixtures!$A$2:$H$49,8) -> 2.37 | H38: =VLOOKUP($B38,Fixtures!$A$2:$H$49,7) -> 3.1 | I38: away | J38: =_xludf.IFS(K38=F38,D38,K38=G38,E38,K38=H38,"Draw",K38="","") -> #NAME? | K38: =_xludf.IFS(I38="home",F38,I38="away",G38,I38="draw",H38,I38="favourite",MIN(F38:H38),I38="outsider",MAX(F38:H38),I38="random",INDEX(F38:H38,1,RANDBETWEEN(1,3)),I38="","") -> #NAME?
A39: 4 | B39: 8 | C39: =VLOOKUP($B39,Fixtures!$A$2:$H$49,4) -> 1 | D39: =VLOOKUP($B39,Fixtures!$A$2:$H$49,2) -> Croatia | E39: =VLOOKUP($B39,Fixtures!$A$2:$H$49,3) -> Nigeria | F39: =VLOOKUP($B39,Fixtures!$A$2:$H$49,6) -> 1.67 | G39: =VLOOKUP($B39,Fixtures!$A$2:$H$49,8) -> 5.5 | H39: =VLOOKUP($B39,Fixtures!$A$2:$H$49,7) -> 3.5 | I39: home | J39: =_xludf.IFS(K39=F39,D39,K39=G39,E39,K39=H39,"Draw",K39="","") -> #NAME? | K39: =_xludf.IFS(I39="home",F39,I39="away",G39,I39="draw",H39,I39="favourite",MIN(F39:H39),I39="outsider",MAX(F39:H39),I39="random",INDEX(F39:H39,1,RANDBETWEEN(1,3)),I39="","") -> #NAME?
A40: 4 | B40: 9 | C40: =VLOOKUP($B40,Fixtures!$A$2:$H$49,4) -> 1 | D40: =VLOOKUP($B40,Fixtures!$A$2:$H$49,2) -> Costa Rica | E40: =VLOOKUP($B40,Fixtures!$A$2:$H$49,3) -> Serbia | F40: =VLOOKUP($B40,Fixtures!$A$2:$H$49,6) -> 4.5 | G40: =VLOOKUP($B40,Fixtures!$A$2:$H$49,8) -> 1.91 | H40: =VLOOKUP($B40,Fixtures!$A$2:$H$49,7) -> 3.1 | I40: away | J40: =_xludf.IFS(K40=F40,D40,K40=G40,E40,K40=H40,"Draw",K40="","") -> #NAME? | K40: =_xludf.IFS(I40="home",F40,I40="away",G40,I40="draw",H40,I40="favourite",MIN(F40:H40),I40="outsider",MAX(F40:H40),I40="random",INDEX(F40:H40,1,RANDBETWEEN(1,3)),I40="","") -> #NAME?
A41: 4 | B41: 10 | C41: =VLOOKUP($B41,Fixtures!$A$2:$H$49,4) -> 1 | D41: =VLOOKUP($B41,Fixtures!$A$2:$H$49,2) -> Germany | E41: =VLOOKUP($B41,Fixtures!$A$2:$H$49,3) -> Mexico | F41: =VLOOKUP($B41,Fixtures!$A$2:$H$49,6) -> 1.4 | G41: =VLOOKUP($B41,Fixtures!$A$2:$H$49,8) -> 7.5 | H41: =VLOOKUP($B41,Fixtures!$A$2:$H$49,7) -> 4.2 | I41: home | J41: =_xludf.IFS(K41=F41,D41,K41=G41,E41,K41=H41,"Draw",K41="","") -> #NAME? | K41: =_xludf.IFS(I41="home",F41,I41="away",G41,I41="draw",H41,I41="favourite",MIN(F41:H41),I41="outsider",MAX(F41:H41),I41="random",INDEX(F41:H41,1,RANDBETWEEN(1,3)),I41="","") -> #NAME?

Sheet Fixtures
A1: fixture_id | B1: home_team | C1: away_team | D1: round | E1: group | F1: home_team_odds | G1: draw_odds | H1: away_team_odds | I1: home_team_odds | J1: draw_odds | K1: away_team_odds
A2: 1 | B2: Russia | C2: Saudi Arabia | D2: 1 | E2: A | F2: 1.4 | G2: 4 | H2: 9 | I2: 1.25 | J2: 4.5 | K2: 9.5
A3: 2 | B3: Egypt | C3: Uruguay | D3: 1 | E3: A | F3: 7 | G3: 3.5 | H3: 1.57 | I3: 4.5 | J3: 3.3 | K3: 1.72
A4: 3 | B4: Morocco | C4: Iran | D4: 1 | E4: B | F4: 2.25 | G4: 2.88 | H4: 3.75 | I4: 2.1 | J4: 3.1 | K4: 3.25
A5: 4 | B5: Portugal | C5: Spain | D5: 1 | E5: B | F5: 4.33 | G5: 3.25 | H5: 1.91 | I5: 4 | J5: 3.3 | K5: 1.83
A6: 5 | B6: France | C6: Australia | D6: 1 | E6: C | F6: 1.2 | G6: 6 | H6: 14 | I6: 1.2 | J6: 5.5 | K6: 15
A7: 6 | B7: Argentina | C7: Iceland | D7: 1 | E7: D | F7: 1.28 | G7: 4.5 | H7: 13 | I7: 1.3 | J7: 4 | K7: 12
A8: 7 | B8: Peru | C8: Denmark | D8: 1 | E8: C | F8: 3.1 | G8: 3.1 | H8: 2.37 | I8: 3.4 | J8: 3 | K8: 2.1
A9: 8 | B9: Croatia | C9: Nigeria | D9: 1 | E9: D | F9: 1.67 | G9: 3.5 | H9: 5.5 | I9: 1.91 | J9: 3.1 | K9: 4
A10: 9 | B10: Costa Rica | C10: Serbia | D10: 1 | E10: E | F10: 4.5 | G10: 3.1 | H10: 1.91 | I10: 3.6 | J10: 3 | K10: 2
A11: 10 | B11: Germany | C11: Mexico | D11: 1 | E11: F | F11: 1.4 | G11: 4.2 | H11: 7.5 | I11: 1.33 | J11: 4 | K11: 10
A12: 11 | B12: Brazil | C12: Switzerland | D12: 1 | E12: E | F12: 1.36 | G12: 4.5 | H12: 8.5 | I12: 1.3 | J12: 5 | K12: 7.5
A13: 12 | B13: Sweden | C13: Korea Republic | D13: 1 | E13: F | F13: 2 | G13: 3.1 | H13: 4 | I13: 1.91 | J13: 3 | K13: 4
... A49: 48 | B49: Panama | C49: Tunisia | D49: 3 | E49: G | F49: 3.5 | G49: 3.1 | H49: 2.1 | I49: 3 | J49: 3 | K49: 2.3

Sheet Teams
A1: code | B1: name | C1: ranking | D1: region | E1: appearances | F1: titles | G1: finals | H1: semi_finals | I1: percent_titles | J1: percent_finals | K1: percent_semi_finals | L1: group | M1: num_played | N1: num_goals_scored | O1: avg_goals_scored | P1: num_goals_conceded | Q1: avg_goals_conceded | R1: odds_to_win
A2: ARG | B2: Argentina | C2: 4 | D2: CONMEBOL | E2: 16 | F2: 2 | G2: 5 | H2: 5 | I2: =F2/E2 -> 0.125 | J2: =G2/E2 -> 0.3125 | K2: =H2/E2 -> 0.3125 | L2: D | M2: 39 | N2: =SUMIF(QualifierResults!$C$2:$C$407,$B2,QualifierResults!$E$2:$E$407)+SUMIF(QualifierResults!$D$2:$D$407,$B2,QualifierResults!$F$2:$F$407) -> 27 | O2: =N2/M2 -> 0.69230769 | P2: =SUMIF(QualifierResults!$C$2:$C$407,$B2,QualifierResults!$F$2:$F$407)+SUMIF(QualifierResults!$D$2:$D$407,$B2,QualifierResults!$E$2:$E$407) -> 22 | Q2: =P2/M2 -> 0.56410256 | R2: 10
A3: AUS | B3: Australia | C3: 39 | D3: AFC | E3: 4 | F3: 0 | G3: 0 | H3: 0 | I3: =F3/E3 -> 0 | J3: =G3/E3 -> 0 | K3: =H3/E3 -> 0 | L3: C | M3: 39 | N3: =SUMIF(QualifierResults!$C$2:$C$407,$B3,QualifierResults!$E$2:$E$407)+SUMIF(QualifierResults!$D$2:$D$407,$B3,QualifierResults!$F$2:$F$407) -> 57 | O3: =N3/M3 -> 1.4615385 | P3: =SUMIF(QualifierResults!$C$2:$C$407,$B3,QualifierResults!$F$2:$F$407)+SUMIF(QualifierResults!$D$2:$D$407,$B3,QualifierResults!$E$2:$E$407) -> 25 | Q3: =P3/M3 -> 0.64102564 | R3: 301
A4: BEL | B4: Belgium | C4: 5 | D4: UEFA | E4: 12 | F4: 0 | G4: 0 | H4: 1 | I4: =F4/E4 -> 0 | J4: =G4/E4 -> 0 | K4: =H4/E4 -> 0.083333333 | L4: G | M4: 15 | N4: =SUMIF(QualifierResults!$C$2:$C$407,$B4,QualifierResults!$E$2:$E$407)+SUMIF(QualifierResults!$D$2:$D$407,$B4,QualifierResults!$F$2:$F$407) -> 43 | O4: =N4/M4 -> 2.8666667 | P4: =SUMIF(QualifierResults!$C$2:$C$407,$B4,QualifierResults!$F$2:$F$407)+SUMIF(QualifierResults!$D$2:$D$407,$B4,QualifierResults!$E$2:$E$407) -> 6 | Q4: =P4/M4 -> 0.4 | R4: 11
A5: BRA | B5: Brazil | C5: 2 | D5: CONMEBOL | E5: 20 | F5: 5 | G5: 7 | H5: 11 | I5: =F5/E5 -> 0.25 | J5: =G5/E5 -> 0.35 | K5: =H5/E5 -> 0.55 | L5: E | M5: 39 | N5: =SUMIF(QualifierResults!$C$2:$C$407,$B5,QualifierResults!$E$2:$E$407)+SUMIF(QualifierResults!$D$2:$D$407,$B5,QualifierResults!$F$2:$F$407) -> 59 | O5: =N5/M5 -> 1.5128205 | P5: =SUMIF(QualifierResults!$C$2:$C$407,$B5,QualifierResults!$F$2:$F$407)+SUMIF(QualifierResults!$D$2:$D$407,$B5,QualifierResults!$E$2:$E$407) -> 17 | Q5: =P5/M5 -> 0.43589744 | R5: 5.5
A6: COL | B6: Colombia | C6: 13 | D6: CONMEBOL | E6: 5 | F6: 0 | G6: 0 | H6: 0 | I6: =F6/E6 -> 0 | J6: =G6/E6 -> 0 | K6: =H6/E6 -> 0 | L6: H | M6: 39 | N6: =SUMIF(QualifierResults!$C$2:$C$407,$B6,QualifierResults!$E$2:$E$407)+SUMIF(QualifierResults!$D$2:$D$407,$B6,QualifierResults!$F$2:$F$407) -> 28 | O6: =N6/M6 -> 0.71794872 | P6: =SUMIF(QualifierResults!$C$2:$C$407,$B6,QualifierResults!$F$2:$F$407)+SUMIF(QualifierResults!$D$2:$D$407,$B6,QualifierResults!$E$2:$E$407) -> 31 | Q6: =P6/M6 -> 0.79487179 | R6: 34
A7: CRC | B7: Costa Rica | C7: 26 | D7: CONCACAF | E7: 4 | F7: 0 | G7: 0 | H7: 0 | I7: =F7/E7 -> 0 | J7: =G7/E7 -> 0 | K7: =H7/E7 -> 0 | L7: E | M7: 30 | N7: =SUMIF(QualifierResults!$C$2:$C$407,$B7,QualifierResults!$E$2:$E$407)+SUMIF(QualifierResults!$D$2:$D$407,$B7,QualifierResults!$F$2:$F$407) -> 26 | O7: =N7/M7 -> 0.86666667 | P7: =SUMIF(QualifierResults!$C$2:$C$407,$B7,QualifierResults!$F$2:$F$407)+SUMIF(QualifierResults!$D$2:$D$407,$B7,QualifierResults!$E$2:$E$407) -> 16 | Q7: =P7/M7 -> 0.53333333 | R7: 501
A8: CRO | B8: Croatia | C8: 17 | D8: UEFA | E8: 4 | F8: 0 | G8: 0 | H8: 1 | I8: =F8/E8 -> 0 | J8: =G8/E8 -> 0 | K8: =H8/E8 -> 0.25 | L8: D | M8: 21 | N8: =SUMIF(QualifierResults!$C$2:$C$407,$B8,QualifierResults!$E$2:$E$407)+SUMIF(QualifierResults!$D$2:$D$407,$B8,QualifierResults!$F$2:$F$407) -> 21 | O8: =N8/M8 -> 1 | P8: =SUMIF(QualifierResults!$C$2:$C$407,$B8,QualifierResults!$F$2:$F$407)+SUMIF(QualifierResults!$D$2:$D$407,$B8,QualifierResults!$E$2:$E$407) -> 6 | Q8: =P8/M8 -> 0.28571429 | R8: 34
A9: DEN | B9: Denmark | C9: 12 | D9: UEFA | E9: 4 | F9: 0 | G9: 0 | H9: 0 | I9: =F9/E9 -> 0 | J9: =G9/E9 -> 0 | K9: =H9/E9 -> 0 | L9: C | M9: 21 | N9: =SUMIF(QualifierResults!$C$2:$C$407,$B9,QualifierResults!$E$2:$E$407)+SUMIF(QualifierResults!$D$2:$D$407,$B9,QualifierResults!$F$2:$F$407) -> 31 | O9: =N9/M9 -> 1.4761905 | P9: =SUMIF(QualifierResults!$C$2:$C$407,$B9,QualifierResults!$F$2:$F$407)+SUMIF(QualifierResults!$D$2:$D$407,$B9,QualifierResults!$E$2:$E$407) -> 12 | Q9: =P9/M9 -> 0.57142857 | R9: 81
A10: EGY | B10: Egypt | C10: 31 | D10: CAF | E10: 2 | F10: 0 | G10: 0 | H10: 0 | I10: =F10/E10 -> 0 | J10: =G10/E10 -> 0 | K10: =H10/E10 -> 0 | L10: A | M10: 12 | N10: =SUMIF(QualifierResults!$C$2:$C$407,$B10,QualifierResults!$E$2:$E$407)+SUMIF(QualifierResults!$D$2:$D$407,$B10,QualifierResults!$F$2:$F$407) -> 12 | O10: =N10/M10 -> 1 | P10: =SUMIF(QualifierResults!$C$2:$C$407,$B10,QualifierResults!$F$2:$F$407)+SUMIF(QualifierResults!$D$2:$D$407,$B10,QualifierResults!$E$2:$E$407) -> 5 | Q10: =P10/M10 -> 0.41666667 | R10: 151
A11: ENG | B11: England | C11: 15 | D11: UEFA | E11: 14 | F11: 1 | G11: 1 | H11: 2 | I11: =F11/E11 -> 0.071428571 | J11: =G11/E11 -> 0.071428571 | K11: =H11/E11 -> 0.14285714 | L11: G | M11: 15 | N11: =SUMIF(QualifierResults!$C$2:$C$407,$B11,QualifierResults!$E$2:$E$407)+SUMIF(QualifierResults!$D$2:$D$407,$B11,QualifierResults!$F$2:$F$407) -> 18 | O11: =N11/M11 -> 1.2 | P11: =SUMIF(QualifierResults!$C$2:$C$407,$B11,QualifierResults!$F$2:$F$407)+SUMIF(QualifierResults!$D$2:$D$407,$B11,QualifierResults!$E$2:$E$407) -> 3 | Q11: =P11/M11 -> 0.2 | R11: 17
A12: FRA | B12: France | C12: 9 | D12: UEFA | E12: 14 | F12: 1 | G12: 2 | H12: 5 | I12: =F12/E12 -> 0.071428571 | J12: =G12/E12 -> 0.14285714 | K12: =H12/E12 -> 0.35714286 | L12: C | M12: 18 | N12: =SUMIF(QualifierResults!$C$2:$C$407,$B12,QualifierResults!$E$2:$E$407)+SUMIF(QualifierResults!$D$2:$D$407,$B12,QualifierResults!$F$2:$F$407) -> 21 | O12: =N12/M12 -> 1.1666667 | P12: =SUMIF(QualifierResults!$C$2:$C$407,$B12,QualifierResults!$F$2:$F$407)+SUMIF(QualifierResults!$D$2:$D$407,$B12,QualifierResults!$E$2:$E$407) -> 9 | Q12: =P12/M12 -> 0.5 | R12: 7
A13: GER | B13: Germany | C13: 1 | D13: UEFA | E13: 18 | F13: 4 | G13: 8 | H13: 13 | I13: =F13/E13 -> 0.22222222 | J13: =G13/E13 -> 0.44444444 | K13: =H13/E13 -> 0.72222222 | L13: F | M13: 15 | N13: =SUMIF(QualifierResults!$C$2:$C$407,$B13,QualifierResults!$E$2:$E$407)+SUMIF(QualifierResults!$D$2:$D$407,$B13,QualifierResults!$F$2:$F$407) -> 43 | O13: =N13/M13 -> 2.8666667 | P13: =SUMIF(QualifierResults!$C$2:$C$407,$B13,QualifierResults!$F$2:$F$407)+SUMIF(QualifierResults!$D$2:$D$407,$B13,QualifierResults!$E$2:$E$407) -> 4 | Q13: =P13/M13 -> 0.26666667 | R13: 5.5
A14: ISL | B14: Iceland | C14: 22 | D14: UEFA | E14: 0 | F14: 0 | G14: 0 | H14: 0 | I14: 0 | J14: 0 | K14: 0 | L14: D | M14: 18 | N14: =SUMIF(QualifierResults!$C$2:$C$407,$B14,QualifierResults!$E$2:$E$407)+SUMIF(QualifierResults!$D$2:$D$407,$B14,QualifierResults!$F$2:$F$407) -> 17 | O14: =N14/M14 -> 0.94444444 | P14: =SUMIF(QualifierResults!$C$2:$C$407,$B14,QualifierResults!$F$2:$F$407)+SUMIF(QualifierResults!$D$2:$D$407,$B14,QualifierResults!$E$2:$E$407) -> 9 | Q14: =P14/M14 -> 0.5 | R14: 201
A15: IRN | B15: Iran | C15: 32 | D15: AFC | E15: 4 | F15: 0 | G15: 0 | H15: 0 | I15: =F15/E15 -> 0 | J15: =G15/E15 -> 0 | K15: =H15/E15 -> 0 | L15: B | M15: 33 | N15: =SUMIF(QualifierResults!$C$2:$C$407,$B15,QualifierResults!$E$2:$E$407)+SUMIF(QualifierResults!$D$2:$D$407,$B15,QualifierResults!$F$2:$F$407) -> 37 | O15: =N15/M15 -> 1.1212121 | P15: =SUMIF(QualifierResults!$C$2:$C$407,$B15,QualifierResults!$F$2:$F$407)+SUMIF(QualifierResults!$D$2:$D$407,$B15,QualifierResults!$E$2:$E$407) -> 5 | Q15: =P15/M15 -> 0.15151515 | R15: 501
A16: JPN | B16: Japan | C16: 55 | D16: AFC | E16: 5 | F16: 0 | G16: 0 | H16: 0 | I16: =F16/E16 -> 0 | J16: =G16/E16 -> 0 | K16: =H16/E16 -> 0 | L16: H | M16: 33 | N16: =SUMIF(QualifierResults!$C$2:$C$407,$B16,QualifierResults!$E$2:$E$407)+SUMIF(QualifierResults!$D$2:$D$407,$B16,QualifierResults!$F$2:$F$407) -> 49 | O16: =N16/M16 -> 1.4848485 | P16: =SUMIF(QualifierResults!$C$2:$C$407,$B16,QualifierResults!$F$2:$F$407)+SUMIF(QualifierResults!$D$2:$D$407,$B16,QualifierResults!$E$2:$E$407) -> 10 | Q16: =P16/M16 -> 0.3030303 | R16: 251
A17: KOR | B17: Korea Republic | C17: 59 | D17: AFC | E17: 9 | F17: 0 | G17: 0 | H17: 1 | I17: =F17/E17 -> 0 | J17: =G17/E17 -> 0 | K17: =H17/E17 -> 0.11111111 | L17: F | M17: 28 | N17: =SUMIF(QualifierResults!$C$2:$C$407,$B17,QualifierResults!$E$2:$E$407)+SUMIF(QualifierResults!$D$2:$D$407,$B17,QualifierResults!$F$2:$F$407) -> 35 | O17: =N17/M17 -> 1.25 | P17: =SUMIF(QualifierResults!$C$2:$C$407,$B17,QualifierResults!$F$2:$F$407)+SUMIF(QualifierResults!$D$2:$D$407,$B17,QualifierResults!$E$2:$E$407) -> 11 | Q17: =P17/M17 -> 0.39285714 | R17: 501
A18: MEX | B18: Mexico | C18: 16 | D18: CONCACAF | E18: 15 | F18: 0 | G18: 0 | H18: 0 | I18: =F18/E18 -> 0 | J18: =G18/E18 -> 0 | K18: =H18/E18 -> 0 | L18: F | M18: 27 | N18: =SUMIF(QualifierResults!$C$2:$C$407,$B18,QualifierResults!$E$2:$E$407)+SUMIF(QualifierResults!$D$2:$D$407,$B18,QualifierResults!$F$2:$F$407) -> 28 | O18: =N18/M18 -> 1.037037 | P18: =SUMIF(QualifierResults!$C$2:$C$407,$B18,QualifierResults!$F$2:$F$407)+SUMIF(QualifierResults!$D$2:$D$407,$B18,QualifierResults!$E$2:$E$407) -> 8 | Q18: =P18/M18 -> 0.2962963 | R18: 101
A19: MAR | B19: Morocco | C19: 40 | D19: CAF | E19: 4 | F19: 0 | G19: 0 | H19: 0 | I19: =F19/E19 -> 0 | J19: =G19/E19 -> 0 | K19: =H19/E19 -> 0 | L19: B | M19: 12 | N19: =SUMIF(QualifierResults!$C$2:$C$407,$B19,QualifierResults!$E$2:$E$407)+SUMIF(QualifierResults!$D$2:$D$407,$B19,QualifierResults!$F$2:$F$407) -> 13 | O19: =N19/M19 -> 1.0833333 | P19: =SUMIF(QualifierResults!$C$2:$C$407,$B19,QualifierResults!$F$2:$F$407)+SUMIF(QualifierResults!$D$2:$D$407,$B19,QualifierResults!$E$2:$E$407) -> 1 | Q19: =P19/M19 -> 0.083333333 | R19: 326
A20: NGA | B20: Nigeria | C20: 50 | D20: CAF | E20: 5 | F20: 0 | G20: 0 | H20: 0 | I20: =F20/E20 -> 0 | J20: =G20/E20 -> 0 | K20: =H20/E20 -> 0 | L20: D | M20: 12 | N20: =SUMIF(QualifierResults!$C$2:$C$407,$B20,QualifierResults!$E$2:$E$407)+SUMIF(QualifierResults!$D$2:$D$407,$B20,QualifierResults!$F$2:$F$407) -> 14 | O20: =N20/M20 -> 1.1666667 | P20: =SUMIF(QualifierResults!$C$2:$C$407,$B20,QualifierResults!$F$2:$F$407)+SUMIF(QualifierResults!$D$2:$D$407,$B20,QualifierResults!$E$2:$E$407) -> 4 | Q20: =P20/M20 -> 0.33333333 | R20: 201
A21: PAN | B21: Panama | C21: 56 | D21: CONCACAF | E21: 0 | F21: 0 | G21: 0 | H21: 0 | I21: 0 | J21: 0 | K21: 0 | L21: G | M21: 28 | N21: =SUMIF(QualifierResults!$C$2:$C$407,$B21,QualifierResults!$E$2:$E$407)+SUMIF(QualifierResults!$D$2:$D$407,$B21,QualifierResults!$F$2:$F$407) -> 16 | O21: =N21/M21 -> 0.57142857 | P21: =SUMIF(QualifierResults!$C$2:$C$407,$B21,QualifierResults!$F$2:$F$407)+SUMIF(QualifierResults!$D$2:$D$407,$B21,QualifierResults!$E$2:$E$407) -> 18 | Q21: =P21/M21 -> 0.64285714 | R21: 501
A22: PER | B22: Peru | C22: 11 | D22: CONMEBOL | E22: 4 | F22: 0 | G22: 0 | H22: 0 | I22: =F22/E22 -> 0 | J22: =G22/E22 -> 0 | K22: =H22/E22 -> 0 | L22: C | M22: 42 | N22: =SUMIF(QualifierResults!$C$2:$C$407,$B22,QualifierResults!$E$2:$E$407)+SUMIF(QualifierResults!$D$2:$D$407,$B22,QualifierResults!$F$2:$F$407) -> 34 | O22: =N22/M22 -> 0.80952381 | P22: =SUMIF(QualifierResults!$C$2:$C$407,$B22,QualifierResults!$F$2:$F$407)+SUMIF(QualifierResults!$D$2:$D$407,$B22,QualifierResults!$E$2:$E$407) -> 37 | Q22: =P22/M22 -> 0.88095238 | R22: 201
A23: POL | B23: Poland | C23: 7 | D23: UEFA | E23: 7 | F23: 0 | G23: 0 | H23: 2 | I23: =F23/E23 -> 0 | J23: =G23/E23 -> 0 | K23: =H23/E23 -> 0.28571429 | L23: H | M23: 18 | N23: =SUMIF(QualifierResults!$C$2:$C$407,$B23,QualifierResults!$E$2:$E$407)+SUMIF(QualifierResults!$D$2:$D$407,$B23,QualifierResults!$F$2:$F$407) -> 31 | O23: =N23/M23 -> 1.7222222 | P23: =SUMIF(QualifierResults!$C$2:$C$407,$B23,QualifierResults!$F$2:$F$407)+SUMIF(QualifierResults!$D$2:$D$407,$B23,QualifierResults!$E$2:$E$407) -> 20 | Q23: =P23/M23 -> 1.1111111 | R23: 51
A24: POR | B24: Portugal | C24: 3 | D24: UEFA | E24: 6 | F24: 0 | G24: 0 | H24: 2 | I24: =F24/E24 -> 0 | J24: =G24/E24 -> 0 | K24: =H24/E24 -> 0.33333333 | L24: B | M24: 19 | N24: =SUMIF(QualifierResults!$C$2:$C$407,$B24,QualifierResults!$E$2:$E$407)+SUMIF(QualifierResults!$D$2:$D$407,$B24,QualifierResults!$F$2:$F$407) -> 34 | O24: =N24/M24 -> 1.7894737 | P24: =SUMIF(QualifierResults!$C$2:$C$407,$B24,QualifierResults!$F$2:$F$407)+SUMIF(QualifierResults!$D$2:$D$407,$B24,QualifierResults!$E$2:$E$407) -> 6 | Q24: =P24/M24 -> 0.31578947 | R24: 21
A25: RUS | B25: Russia | C25: 65 | D25: UEFA | E25: 10 | F25: 0 | G25: 0 | H25: 1 | I25: =F25/E25 -> 0 | J25: =G25/E25 -> 0 | K25: =H25/E25 -> 0.1 | L25: A | M25: 0 | N25: =SUMIF(QualifierResults!$C$2:$C$407,$B25,QualifierResults!$E$2:$E$407)+SUMIF(QualifierResults!$D$2:$D$407,$B25,QualifierResults!$F$2:$F$407) -> 0 | O25: 0 | P25: =SUMIF(QualifierResults!$C$2:$C$407,$B25,QualifierResults!$F$2:$F$407)+SUMIF(QualifierResults!$D$2:$D$407,$B25,QualifierResults!$E$2:$E$407) -> 0 | Q25: 0 | R25: 41
A26: KSA | B26: Saudi Arabia | C26: 63 | D26: AFC | E26: 4 | F26: 0 | G26: 0 | H26: 0 | I26: =F26/E26 -> 0 | J26: =G26/E26 -> 0 | K26: =H26/E26 -> 0 | L26: A | M26: 33 | N26: =SUMIF(QualifierResults!$C$2:$C$407,$B26,QualifierResults!$E$2:$E$407)+SUMIF(QualifierResults!$D$2:$D$407,$B26,QualifierResults!$F$2:$F$407) -> 51 | O26: =N26/M26 -> 1.5454545 | P26: =SUMIF(QualifierResults!$C$2:$C$407,$B26,QualifierResults!$F$2:$F$407)+SUMIF(QualifierResults!$D$2:$D$407,$B26,QualifierResults!$E$2:$E$407) -> 21 | Q26: =P26/M26 -> 0.63636364 | R26: 501
A27: SEN | B27: Senegal | C27: 23 | D27: CAF | E27: 1 | F27: 0 | G27: 0 | H27: 0 | I27: =F27/E27 -> 0 | J27: =G27/E27 -> 0 | K27: =H27/E27 -> 0 | L27: H | M27: 13 | N27: =SUMIF(QualifierResults!$C$2:$C$407,$B27,QualifierResults!$E$2:$E$407)+SUMIF(QualifierResults!$D$2:$D$407,$B27,QualifierResults!$F$2:$F$407) -> 16 | O27: =N27/M27 -> 1.2307692 | P27: =SUMIF(QualifierResults!$C$2:$C$407,$B27,QualifierResults!$F$2:$F$407)+SUMIF(QualifierResults!$D$2:$D$407,$B27,QualifierResults!$E$2:$E$407) -> 7 | Q27: =P27/M27 -> 0.53846154 | R27: 201
A28: SRB | B28: Serbia | C28: 37 | D28: UEFA | E28: 11 | F28: 0 | G28: 0 | H28: 2 | I28: =F28/E28 -> 0 | J28: =G28/E28 -> 0 | K28: =H28/E28 -> 0.18181818 | L28: E | M28: 15 | N28: =SUMIF(QualifierResults!$C$2:$C$407,$B28,QualifierResults!$E$2:$E$407)+SUMIF(QualifierResults!$D$2:$D$407,$B28,QualifierResults!$F$2:$F$407) -> 19 | O28: =N28/M28 -> 1.2666667 | P28: =SUMIF(QualifierResults!$C$2:$C$407,$B28,QualifierResults!$F$2:$F$407)+SUMIF(QualifierResults!$D$2:$D$407,$B28,QualifierResults!$E$2:$E$407) -> 10 | Q28: =P28/M28 -> 0.66666667 | R28: 126
A29: ESP | B29: Spain | C29: 6 | D29: UEFA | E29: 14 | F29: 1 | G29: 1 | H29: 2 | I29: =F29/E29 -> 0.071428571 | J29: =G29/E29 -> 0.071428571 | K29: =H29/E29 -> 0.14285714 | L29: B | M29: 15 | N29: =SUMIF(QualifierResults!$C$2:$C$407,$B29,QualifierResults!$E$2:$E$407)+SUMIF(QualifierResults!$D$2:$D$407,$B29,QualifierResults!$F$2:$F$407) -> 36 | O29: =N29/M29 -> 2.4 | P29: =SUMIF(QualifierResults!$C$2:$C$407,$B29,QualifierResults!$F$2:$F$407)+SUMIF(QualifierResults!$D$2:$D$407,$B29,QualifierResults!$E$2:$E$407) -> 3 | Q29: =P29/M29 -> 0.2 | R29: 6.5
A30: SWE | B30: Sweden | C30: 18 | D30: UEFA | E30: 11 | F30: 0 | G30: 1 | H30: 4 | I30: =F30/E30 -> 0 | J30: =G30/E30 -> 0.090909091 | K30: =H30/E30 -> 0.36363636 | L30: F | M30: 21 | N30: =SUMIF(QualifierResults!$C$2:$C$407,$B30,QualifierResults!$E$2:$E$407)+SUMIF(QualifierResults!$D$2:$D$407,$B30,QualifierResults!$F$2:$F$407) -> 30 | O30: =N30/M30 -> 1.4285714 | P30: =SUMIF(QualifierResults!$C$2:$C$407,$B30,QualifierResults!$F$2:$F$407)+SUMIF(QualifierResults!$D$2:$D$407,$B30,QualifierResults!$E$2:$E$407) -> 12 | Q30: =P30/M30 -> 0.57142857 | R30: 151
A31: SUI | B31: Switzerland | C31: 8 | D31: UEFA | E31: 10 | F31: 0 | G31: 0 | H31: 0 | I31: =F31/E31 -> 0 | J31: =G31/E31 -> 0 | K31: =H31/E31 -> 0 | L31: E | M31: 21 | N31: =SUMIF(QualifierResults!$C$2:$C$407,$B31,QualifierResults!$E$2:$E$407)+SUMIF(QualifierResults!$D$2:$D$407,$B31,QualifierResults!$F$2:$F$407) -> 26 | O31: =N31/M31 -> 1.2380952 | P31: =SUMIF(QualifierResults!$C$2:$C$407,$B31,QualifierResults!$F$2:$F$407)+SUMIF(QualifierResults!$D$2:$D$407,$B31,QualifierResults!$E$2:$E$407) -> 9 | Q31: =P31/M31 -> 0.42857143 | R31: 101
