Workbook

Sheet Basic Analysis
A1: 2018 | B1: Betting Outcomes | H1: 2014 | I1: Betting Outcomes | O1: 2010 | P1: Betting Outcomes | V1: 2006 | W1: Betting Outcomes
A3: Overall | H3: Overall | O3: Overall | V3: Overall
A4: Favourites | B4: =COUNTIFS('All Group Fixtures'!$A$2:$A$1048,A$1,'All Group Fixtures'!$N$2:$N$1048,"favourite") -> 0 | C4: =B4/B7 -> 0 | H4: Favourites | I4: =COUNTIFS('All Group Fixtures'!$A$2:$A$1048,H$1,'All Group Fixtures'!$N$2:$N$1048,"favourite") -> 27 | J4: =I4/I7 -> 0.5625 | O4: Favourites | P4: =COUNTIFS('All Group Fixtures'!$A$2:$A$1048,O$1,'All Group Fixtures'!$N$2:$N$1048,"favourite") -> 24 | Q4: =P4/P7 -> 0.5 | V4: Favourites | W4: =COUNTIFS('All Group Fixtures'!$A$2:$A$1048,V$1,'All Group Fixtures'!$N$2:$N$1048,"favourite") -> 32 | X4: =W4/W7 -> 0.66666667
A5: Outsiders | B5: =COUNTIFS('All Group Fixtures'!$A$2:$A$1048,A$1,'All Group Fixtures'!$N$2:$N$1048,"outsider") -> 0 | C5: =B5/B7 -> 0 | H5: Outsiders | I5: =COUNTIFS('All Group Fixtures'!$A$2:$A$1048,H$1,'All Group Fixtures'!$N$2:$N$1048,"outsider") -> 12 | J5: =I5/I7 -> 0.25 | O5: Outsiders | P5: =COUNTIFS('All Group Fixtures'!$A$2:$A$1048,O$1,'All Group Fixtures'!$N$2:$N$1048,"outsider") -> 10 | Q5: =P5/P7 -> 0.20833333 | V5: Outsiders | W5: =COUNTIFS('All Group Fixtures'!$A$2:$A$1048,V$1,'All Group Fixtures'!$N$2:$N$1048,"outsider") -> 5 | X5: =W5/W7 -> 0.10416667
A6: Draw | B6: =COUNTIFS('All Group Fixtures'!$A$2:$A$1048,A$1,'All Group Fixtures'!$N$2:$N$1048,"draw") -> 1 | C6: =B6/B7 -> 1 | H6: Draw | I6: =COUNTIFS('All Group Fixtures'!$A$2:$A$1048,H$1,'All Group Fixtures'!$N$2:$N$1048,"draw") -> 9 | J6: =I6/I7 -> 0.1875 | O6: Draw | P6: =COUNTIFS('All Group Fixtures'!$A$2:$A$1048,O$1,'All Group Fixtures'!$N$2:$N$1048,"draw") -> 14 | Q6: =P6/P7 -> 0.29166667 | V6: Draw | W6: =COUNTIFS('All Group Fixtures'!$A$2:$A$1048,V$1,'All Group Fixtures'!$N$2:$N$1048,"draw") -> 11 | X6: =W6/W7 -> 0.22916667
A7: Total | B7: =SUM(B4:B6) -> 1 | C7: =SUM(C4:C6) -> 1 | H7: Total | I7: =SUM(I4:I6) -> 48 | J7: =SUM(J4:J6) -> 1 | O7: Total | P7: =SUM(P4:P6) -> 48 | Q7: =SUM(Q4:Q6) -> 1 | V7: Total | W7: =SUM(W4:W6) -> 48 | X7: =SUM(X4:X6) -> 1
A10: Round | B10: 1 | H10: Round | I10: 1 | O10: Round | P10: 1 | V10: Round | W10: 1
A11: Favourites | B11: =COUNTIFS('All Group Fixtures'!$A$2:$A$1048,A$1,'All Group Fixtures'!$N$2:$N$1048,"favourite",'All Group Fixtures'!$C$2:$C$1048,B10) -> 0 | C11: =B11/B14 -> 0 | H11: Favourites | I11: =COUNTIFS('All Group Fixtures'!$A$2:$A$1048,H$1,'All Group Fixtures'!$N$2:$N$1048,"favourite",'All Group Fixtures'!$C$2:$C$1048,I10) -> 10 | J11: =I11/I14 -> 0.625 | O11: Favourites | P11: =COUNTIFS('All Group Fixtures'!$A$2:$A$1048,O$1,'All Group Fixtures'!$N$2:$N$1048,"favourite",'All Group Fixtures'!$C$2:$C$1048,P10) -> 7 | Q11: =P11/P14 -> 0.4375 | V11: Favourites | W11: =COUNTIFS('All Group Fixtures'!$A$2:$A$1048,V$1,'All Group Fixtures'!$N$2:$N$1048,"favourite",'All Group Fixtures'!$C$2:$C$1048,W10) -> 11 | X11: =W11/W14 -> 0.6875
A12: Outsiders | B12: =COUNTIFS('All Group Fixtures'!$A$2:$A$1048,A$1,'All Group Fixtures'!$N$2:$N$1048,"outsider",'All Group Fixtures'!$C$2:$C$1048,B10) -> 0 | C12: =B12/B14 -> 0 | H12: Outsiders | I12: =COUNTIFS('All Group Fixtures'!$A$2:$A$1048,H$1,'All Group Fixtures'!$N$2:$N$1048,"outsider",'All Group Fixtures'!$C$2:$C$1048,I10) -> 4 | J12: =I12/I14 -> 0.25 | O12: Outsiders | P12: =COUNTIFS('All Group Fixtures'!$A$2:$A$1048,O$1,'All Group Fixtures'!$N$2:$N$1048,"outsider",'All Group Fixtures'!$C$2:$C$1048,P10) -> 3 | Q12: =P12/P14 -> 0.1875 | V12: Outsiders | W12: =COUNTIFS('All Group Fixtures'!$A$2:$A$1048,V$1,'All Group Fixtures'!$N$2:$N$1048,"outsider",'All Group Fixtures'!$C$2:$C$1048,W10) -> 2 | X12: =W12/W14 -> 0.125
A13: Draw | B13: =COUNTIFS('All Group Fixtures'!$A$2:$A$1048,A$1,'All Group Fixtures'!$N$2:$N$1048,"draw",'All Group Fixtures'!$C$2:$C$1048,B10) -> 1 | C13: =B13/B14 -> 1 | H13: Draw | I13: =COUNTIFS('All Group Fixtures'!$A$2:$A$1048,H$1,'All Group Fixtures'!$N$2:$N$1048,"draw",'All Group Fixtures'!$C$2:$C$1048,I10) -> 2 | J13: =I13/I14 -> 0.125 | O13: Draw | P13: =COUNTIFS('All Group Fixtures'!$A$2:$A$1048,O$1,'All Group Fixtures'!$N$2:$N$1048,"draw",'All Group Fixtures'!$C$2:$C$1048,P10) -> 6 | Q13: =P13/P14 -> 0.375 | V13: Draw | W13: =COUNTIFS('All Group Fixtures'!$A$2:$A$1048,V$1,'All Group Fixtures'!$N$2:$N$1048,"draw",'All Group Fixtures'!$C$2:$C$1048,W10) -> 3 | X13: =W13/W14 -> 0.1875
A14: Total | B14: =SUM(B11:B13) -> 1 | C14: =SUM(C11:C13) -> 1 | H14: Total | I14: =SUM(I11:I13) -> 16 | J14: =SUM(J11:J13) -> 1 | O14: Total | P14: =SUM(P11:P13) -> 16 | Q14: =SUM(Q11:Q13) -> 1 | V14: Total | W14: =SUM(W11:W13) -> 16 | X14: =SUM(X11:X13) -> 1
A15: Payout | H15: Payout | I15: =PRODUCT('All Group Fixtures'!P98:P113) -> 1367570.8 | O15: Payout | P15: =PRODUCT('All Group Fixtures'!P50:P65) -> 11533205
A18: Round | B18: 2 | H18: Round | I18: 2 | O18: Round | P18: 2 | V18: Round | W18: 2
A19: Favourites | B19: =COUNTIFS('All Group Fixtures'!$A$2:$A$1048,A$1,'All Group Fixtures'!$N$2:$N$1048,"favourite",'All Group Fixtures'!$C$2:$C$1048,B18) -> 0 | C19: =B19/B22 -> #DIV/0! | H19: Favourites | I19: =COUNTIFS('All Group Fixtures'!$A$2:$A$1048,H$1,'All Group Fixtures'!$N$2:$N$1048,"favourite",'All Group Fixtures'!$C$2:$C$1048,I18) -> 7 | J19: =I19/I22 -> 0.4375 | O19: Favourites | P19: =COUNTIFS('All Group Fixtures'!$A$2:$A$1048,O$1,'All Group Fixtures'!$N$2:$N$1048,"favourite",'All Group Fixtures'!$C$2:$C$1048,P18) -> 9 | Q19: =P19/P22 -> 0.5625 | V19: Favourites | W19: =COUNTIFS('All Group Fixtures'!$A$2:$A$1048,V$1,'All Group Fixtures'!$N$2:$N$1048,"favourite",'All Group Fixtures'!$C$2:$C$1048,W18) -> 10 | X19: =W19/W22 -> 0.625
A20: Outsiders | B20: =COUNTIFS('All Group Fixtures'!$A$2:$A$1048,A$1,'All Group Fixtures'!$N$2:$N$1048,"outsider",'All Group Fixtures'!$C$2:$C$1048,B18) -> 0 | C20: =B20/B22 -> #DIV/0! | H20: Outsiders | I20: =COUNTIFS('All Group Fixtures'!$A$2:$A$1048,H$1,'All Group Fixtures'!$N$2:$N$1048,"outsider",'All Group Fixtures'!$C$2:$C$1048,I18) -> 5 | J20: =I20/I22 -> 0.3125 | O20: Outsiders | P20: =COUNTIFS('All Group Fixtures'!$A$2:$A$1048,O$1,'All Group Fixtures'!$N$2:$N$1048,"outsider",'All Group Fixtures'!$C$2:$C$1048,P18) -> 3 | Q20: =P20/P22 -> 0.1875 | V20: Outsiders | W20: =COUNTIFS('All Group Fixtures'!$A$2:$A$1048,V$1,'All Group Fixtures'!$N$2:$N$1048,"outsider",'All Group Fixtures'!$C$2:$C$1048,W18) -> 2 | X20: =W20/W22 -> 0.125
A21: Draw | B21: =COUNTIFS('All Group Fixtures'!$A$2:$A$1048,A$1,'All Group Fixtures'!$N$2:$N$1048,"draw",'All Group Fixtures'!$C$2:$C$1048,B18) -> 0 | C21: =B21/B22 -> #DIV/0! | H21: Draw | I21: =COUNTIFS('All Group Fixtures'!$A$2:$A$1048,H$1,'All Group Fixtures'!$N$2:$N$1048,"draw",'All Group Fixtures'!$C$2:$C$1048,I18) -> 4 | J21: =I21/I22 -> 0.25 | O21: Draw | P21: =COUNTIFS('All Group Fixtures'!$A$2:$A$1048,O$1,'All Group Fixtures'!$N$2:$N$1048,"draw",'All Group Fixtures'!$C$2:$C$1048,P18) -> 4 | Q21: =P21/P22 -> 0.25 | V21: Draw | W21: =COUNTIFS('All Group Fixtures'!$A$2:$A$1048,V$1,'All Group Fixtures'!$N$2:$N$1048,"draw",'All Group Fixtures'!$C$2:$C$1048,W18) -> 4 | X21: =W21/W22 -> 0.25
A22: Total | B22: =SUM(B19:B21) -> 0 | C22: =SUM(C19:C21) -> #DIV/0! | H22: Total | I22: =SUM(I19:I21) -> 16 | J22: =SUM(J19:J21) -> 1 | O22: Total | P22: =SUM(P19:P21) -> 16 | Q22: =SUM(Q19:Q21) -> 1 | V22: Total | W22: =SUM(W19:W21) -> 16 | X22: =SUM(X19:X21) -> 1
H23: Payout | I23: =PRODUCT('All Group Fixtures'!P114:P129) -> 24239010 | O23: Payout | P23: =PRODUCT('All Group Fixtures'!P66:P81) -> 4787089.4
A26: Round | B26: 3 | H26: Round | I26: 3 | O26: Round | P26: 3 | V26: Round | W26: 3
A27: Favourites | B27: =COUNTIFS('All Group Fixtures'!$A$2:$A$1048,A$1,'All Group Fixtures'!$N$2:$N$1048,"favourite",'All Group Fixtures'!$C$2:$C$1048,B26) -> 0 | C27: =B27/B30 -> #DIV/0! | H27: Favourites | I27: =COUNTIFS('All Group Fixtures'!$A$2:$A$1048,H$1,'All Group Fixtures'!$N$2:$N$1048,"favourite",'All Group Fixtures'!$C$2:$C$1048,I26) -> 10 | J27: =I27/I30 -> 0.625 | O27: Favourites | P27: =COUNTIFS('All Group Fixtures'!$A$2:$A$1048,O$1,'All Group Fixtures'!$N$2:$N$1048,"favourite",'All Group Fixtures'!$C$2:$C$1048,P26) -> 8 | Q27: =P27/P30 -> 0.5 | V27: Favourites | W27: =COUNTIFS('All Group Fixtures'!$A$2:$A$1048,V$1,'All Group Fixtures'!$N$2:$N$1048,"favourite",'All Group Fixtures'!$C$2:$C$1048,W26) -> 11 | X27: =W27/W30 -> 0.6875
A28: Outsiders | B28: =COUNTIFS('All Group Fixtures'!$A$2:$A$1048,A$1,'All Group Fixtures'!$N$2:$N$1048,"outsider",'All Group Fixtures'!$C$2:$C$1048,B26) -> 0 | C28: =B28/B30 -> #DIV/0! | H28: Outsiders | I28: =COUNTIFS('All Group Fixtures'!$A$2:$A$1048,H$1,'All Group Fixtures'!$N$2:$N$1048,"outsider",'All Group Fixtures'!$C$2:$C$1048,I26) -> 3 | J28: =I28/I30 -> 0.1875 | O28: Outsiders | P28: =COUNTIFS('All Group Fixtures'!$A$2:$A$1048,O$1,'All Group Fixtures'!$N$2:$N$1048,"outsider",'All Group Fixtures'!$C$2:$C$1048,P26) -> 4 | Q28: =P28/P30 -> 0.25 | V28: Outsiders | W28: =COUNTIFS('All Group Fixtures'!$A$2:$A$1048,V$1,'All Group Fixtures'!$N$2:$N$1048,"outsider",'All Group Fixtures'!$C$2:$C$1048,W26) -> 1 | X28: =W28/W30 -> 0.0625
A29: Draw | B29: =COUNTIFS('All Group Fixtures'!$A$2:$A$1048,A$1,'All Group Fixtures'!$N$2:$N$1048,"draw",'All Group Fixtures'!$C$2:$C$1048,B26) -> 0 | C29: =B29/B30 -> #DIV/0! | H29: Draw | I29: =COUNTIFS('All Group Fixtures'!$A$2:$A$1048,H$1,'All Group Fixtures'!$N$2:$N$1048,"draw",'All Group Fixtures'!$C$2:$C$1048,I26) -> 3 | J29: =I29/I30 -> 0.1875 | O29: Draw | P29: =COUNTIFS('All Group Fixtures'!$A$2:$A$1048,O$1,'All Group Fixtures'!$N$2:$N$1048,"draw",'All Group Fixtures'!$C$2:$C$1048,P26) -> 4 | Q29: =P29/P30 -> 0.25 | V29: Draw | W29: =COUNTIFS('All Group Fixtures'!$A$2:$A$1048,V$1,'All Group Fixtures'!$N$2:$N$1048,"draw",'All Group Fixtures'!$C$2:$C$1048,W26) -> 4 | X29: =W29/W30 -> 0.25
A30: Total | B30: =SUM(B27:B29) -> 0 | C30: =SUM(C27:C29) -> #DIV/0! | H30: Total | I30: =SUM(I27:I29) -> 16 | J30: =SUM(J27:J29) -> 1 | O30: Total | P30: =SUM(P27:P29) -> 16 | Q30: =SUM(Q27:Q29) -> 1 | V30: Total | W30: =SUM(W27:W29) -> 16 | X30: =SUM(X27:X29) -> 1
H31: Payout | I31: =PRODUCT('All Group Fixtures'!P130:P146) -> 1653835.5 | O31: Payout | P31: =PRODUCT('All Group Fixtures'!P82:P97) -> 4586134.9
A34: =A1&" Group Standings" -> 2018 Group Standings | H34: =H1&" Group Standings" -> 2014 Group Standings | O34: =O1&" Group Standings" -> 2010 Group Standings | V34: =V1&" Group Standings" -> 2006 Group Standings
A35: Group Winners | H35: Group Winners | O35: Group Winners | V35: Group Winners
A36: Favourite | B36: 3 | C36: =COUNTIF('2014 Group Standings'!$K$4,B36)+COUNTIF('2014 Group Standings'!$K$10,B36)+COUNTIF('2014 Group Standings'!$K$16,B36)+COUNTIF('2014 Group Standings'!$K$22,B36)+COUNTIF('2014 Group Standings'!$K$28,B36)+COUNTIF('2014 Group Standings'!$K$34,B36)+COUNTIF('2014 Group Standings'!$K$40,B36)+COUNTIF('2014 Group Standings'!$K$46,B36) -> 6 | D36: =C36/C$40 -> 0.75 | H36: Favourite | I36: 3 | J36: =COUNTIF('2014 Group Standings'!$K$4,I36)+COUNTIF('2014 Group Standings'!$K$10,I36)+COUNTIF('2014 Group Standings'!$K$16,I36)+COUNTIF('2014 Group Standings'!$K$22,I36)+COUNTIF('2014 Group Standings'!$K$28,I36)+COUNTIF('2014 Group Standings'!$K$34,I36)+COUNTIF('2014 Group Standings'!$K$40,I36)+COUNTIF('2014 Group Standings'!$K$46,I36) -> 6 | K36: =J36/J$40 -> 0.75 | O36: Favourite | P36: 3 | Q36: =COUNTIF('2010 Group Standings'!$K$4,P36)+COUNTIF('2010 Group Standings'!$K$10,P36)+COUNTIF('2010 Group Standings'!$K$16,P36)+COUNTIF('2010 Group Standings'!$K$22,P36)+COUNTIF('2010 Group Standings'!$K$28,P36)+COUNTIF('2010 Group Standings'!$K$34,P36)+COUNTIF('2010 Group Standings'!$K$40,P36)+COUNTIF('2010 Group Standings'!$K$46,P36) -> 5 | R36: =Q36/Q$40 -> 0.625 | V36: Favourite | W36: 3 | X36: =COUNTIF('2010 Group Standings'!$K$4,W36)+COUNTIF('2010 Group Standings'!$K$10,W36)+COUNTIF('2010 Group Standings'!$K$16,W36)+COUNTIF('2010 Group Standings'!$K$22,W36)+COUNTIF('2010 Group Standings'!$K$28,W36)+COUNTIF('2010 Group Standings'!$K$34,W36)+COUNTIF('2010 Group Standings'!$K$40,W36)+COUNTIF('2010 Group Standings'!$K$46,W36) -> 5 | Y36: =X36/X$40 -> 0.625
B37: 2 | C37: =COUNTIF('2014 Group Standings'!$K$4,B37)+COUNTIF('2014 Group Standings'!$K$10,B37)+COUNTIF('2014 Group Standings'!$K$16,B37)+COUNTIF('2014 Group Standings'!$K$22,B37)+COUNTIF('2014 Group Standings'!$K$28,B37)+COUNTIF('2014 Group Standings'!$K$34,B37)+COUNTIF('2014 Group Standings'!$K$40,B37)+COUNTIF('2014 Group Standings'!$K$46,B37) -> 0 | D37: =C37/C$40 -> 0 | I37: 2 | J37: =COUNTIF('2014 Group Standings'!$K$4,I37)+COUNTIF('2014 Group Standings'!$K$10,I37)+COUNTIF('2014 Group Standings'!$K$16,I37)+COUNTIF('2014 Group Standings'!$K$22,I37)+COUNTIF('2014 Group Standings'!$K$28,I37)+COUNTIF('2014 Group Standings'!$K$34,I37)+COUNTIF('2014 Group Standings'!$K$40,I37)+COUNTIF('2014 Group Standings'!$K$46,I37) -> 0 | K37: =J37/J$40 -> 0 | P37: 2 | Q37: =COUNTIF('2010 Group Standings'!$K$4,P37)+COUNTIF('2010 Group Standings'!$K$10,P37)+COUNTIF('2010 Group Standings'!$K$16,P37)+COUNTIF('2010 Group Standings'!$K$22,P37)+COUNTIF('2010 Group Standings'!$K$28,P37)+COUNTIF('2010 Group Standings'!$K$34,P37)+COUNTIF('2010 Group Standings'!$K$40,P37)+COUNTIF('2010 Group Standings'!$K$46,P37) -> 3 | R37: =Q37/Q$40 -> 0.375 | W37: 2 | X37: =COUNTIF('2010 Group Standings'!$K$4,W37)+COUNTIF('2010 Group Standings'!$K$10,W37)+COUNTIF('2010 Group Standings'!$K$16,W37)+COUNTIF('2010 Group Standings'!$K$22,W37)+COUNTIF('2010 Group Standings'!$K$28,W37)+COUNTIF('2010 Group Standings'!$K$34,W37)+COUNTIF('2010 Group Standings'!$K$40,W37)+COUNTIF('2010 Group Standings'!$K$46,W37) -> 3 | Y37: =X37/X$40 -> 0.375
B38: 1 | C38: =COUNTIF('2014 Group Standings'!$K$4,B38)+COUNTIF('2014 Group Standings'!$K$10,B38)+COUNTIF('2014 Group Standings'!$K$16,B38)+COUNTIF('2014 Group Standings'!$K$22,B38)+COUNTIF('2014 Group Standings'!$K$28,B38)+COUNTIF('2014 Group Standings'!$K$34,B38)+COUNTIF('2014 Group Standings'!$K$40,B38)+COUNTIF('2014 Group Standings'!$K$46,B38) -> 1 | D38: =C38/C$40 -> 0.125 | I38: 1 | J38: =COUNTIF('2014 Group Standings'!$K$4,I38)+COUNTIF('2014 Group Standings'!$K$10,I38)+COUNTIF('2014 Group Standings'!$K$16,I38)+COUNTIF('2014 Group Standings'!$K$22,I38)+COUNTIF('2014 Group Standings'!$K$28,I38)+COUNTIF('2014 Group Standings'!$K$34,I38)+COUNTIF('2014 Group Standings'!$K$40,I38)+COUNTIF('2014 Group Standings'!$K$46,I38) -> 1 | K38: =J38/J$40 -> 0.125 | P38: 1 | Q38: =COUNTIF('2010 Group Standings'!$K$4,P38)+COUNTIF('2010 Group Standings'!$K$10,P38)+COUNTIF('2010 Group Standings'!$K$16,P38)+COUNTIF('2010 Group Standings'!$K$22,P38)+COUNTIF('2010 Group Standings'!$K$28,P38)+COUNTIF('2010 Group Standings'!$K$34,P38)+COUNTIF('2010 Group Standings'!$K$40,P38)+COUNTIF('2010 Group Standings'!$K$46,P38) -> 0 | R38: =Q38/Q$40 -> 0 | W38: 1 | X38: =COUNTIF('2010 Group Standings'!$K$4,W38)+COUNTIF('2010 Group Standings'!$K$10,W38)+COUNTIF('2010 Group Standings'!$K$16,W38)+COUNTIF('2010 Group Standings'!$K$22,W38)+COUNTIF('2010 Group Standings'!$K$28,W38)+COUNTIF('2010 Group Standings'!$K$34,W38)+COUNTIF('2010 Group Standings'!$K$40,W38)+COUNTIF('2010 Group Standings'!$K$46,W38) -> 0 | Y38: =X38/X$40 -> 0
A39: Outsider | B39: 0 | C39: =COUNTIF('2014 Group Standings'!$K$4,B39)+COUNTIF('2014 Group Standings'!$K$10,B39)+COUNTIF('2014 Group Standings'!$K$16,B39)+COUNTIF('2014 Group Standings'!$K$22,B39)+COUNTIF('2014 Group Standings'!$K$28,B39)+COUNTIF('2014 Group Standings'!$K$34,B39)+COUNTIF('2014 Group Standings'!$K$40,B39)+COUNTIF('2014 Group Standings'!$K$46,B39) -> 1 | D39: =C39/C$40 -> 0.125 | H39: Outsider | I39: 0 | J39: =COUNTIF('2014 Group Standings'!$K$4,I39)+COUNTIF('2014 Group Standings'!$K$10,I39)+COUNTIF('2014 Group Standings'!$K$16,I39)+COUNTIF('2014 Group Standings'!$K$22,I39)+COUNTIF('2014 Group Standings'!$K$28,I39)+COUNTIF('2014 Group Standings'!$K$34,I39)+COUNTIF('2014 Group Standings'!$K$40,I39)+COUNTIF('2014 Group Standings'!$K$46,I39) -> 1 | K39: =J39/J$40 -> 0.125 | O39: Outsider | P39: 0 | Q39: =COUNTIF('2010 Group Standings'!$K$4,P39)+COUNTIF('2010 Group Standings'!$K$10,P39)+COUNTIF('2010 Group Standings'!$K$16,P39)+COUNTIF('2010 Group Standings'!$K$22,P39)+COUNTIF('2010 Group Standings'!$K$28,P39)+COUNTIF('2010 Group Standings'!$K$34,P39)+COUNTIF('2010 Group Standings'!$K$40,P39)+COUNTIF('2010 Group Standings'!$K$46,P39) -> 0 | R39: =Q39/Q$40 -> 0 | V39: Outsider | W39: 0 | X39: =COUNTIF('2010 Group Standings'!$K$4,W39)+COUNTIF('2010 Group Standings'!$K$10,W39)+COUNTIF('2010 Group Standings'!$K$16,W39)+COUNTIF('2010 Group Standings'!$K$22,W39)+COUNTIF('2010 Group Standings'!$K$28,W39)+COUNTIF('2010 Group Standings'!$K$34,W39)+COUNTIF('2010 Group Standings'!$K$40,W39)+COUNTIF('2010 Group Standings'!$K$46,W39) -> 0 | Y39: =X39/X$40 -> 0
A40: Total | C40: =SUM(C36:C39) -> 8 | D40: =SUM(D36:D39) -> 1 | H40: Total | J40: =SUM(J36:J39) -> 8 | K40: =SUM(K36:K39) -> 1 | O40: Total | Q40: =SUM(Q36:Q39) -> 8 | R40: =SUM(R36:R39) -> 1 | V40: Total | X40: =SUM(X36:X39) -> 8 | Y40: =SUM(Y36:Y39) -> 1
A42: Group Runner Up | H42: Group Runner Up | O42: Group Runner Up | V42: Group Runner Up
A43: Favourite | B43: 3 | C43: =COUNTIF('2014 Group Standings'!$K$5,B43)+COUNTIF('2014 Group Standings'!$K$11,B43)+COUNTIF('2014 Group Standings'!$K$17,B43)+COUNTIF('2014 Group Standings'!$K$23,B43)+COUNTIF('2014 Group Standings'!$K$29,B43)+COUNTIF('2014 Group Standings'!$K$35,B43)+COUNTIF('2014 Group Standings'!$K$41,B43)+COUNTIF('2014 Group Standings'!$K$47,B43) -> 0 | D43: =C43/C$47 -> 0 | H43: Favourite | I43: 3 | J43: =COUNTIF('2014 Group Standings'!$K$5,I43)+COUNTIF('2014 Group Standings'!$K$11,I43)+COUNTIF('2014 Group Standings'!$K$17,I43)+COUNTIF('2014 Group Standings'!$K$23,I43)+COUNTIF('2014 Group Standings'!$K$29,I43)+COUNTIF('2014 Group Standings'!$K$35,I43)+COUNTIF('2014 Group Standings'!$K$41,I43)+COUNTIF('2014 Group Standings'!$K$47,I43) -> 0 | K43: =J43/J$47 -> 0 | O43: Favourite | P43: 3 | Q43: =COUNTIF('2010 Group Standings'!$K$5,P43)+COUNTIF('2010 Group Standings'!$K$11,P43)+COUNTIF('2010 Group Standings'!$K$17,P43)+COUNTIF('2010 Group Standings'!$K$23,P43)+COUNTIF('2010 Group Standings'!$K$29,P43)+COUNTIF('2010 Group Standings'!$K$35,P43)+COUNTIF('2010 Group Standings'!$K$41,P43)+COUNTIF('2010 Group Standings'!$K$47,P43) -> 1 | R43: =Q43/Q$47 -> 0.125 | V43: Favourite | W43: 3 | X43: =COUNTIF('2010 Group Standings'!$K$5,W43)+COUNTIF('2010 Group Standings'!$K$11,W43)+COUNTIF('2010 Group Standings'!$K$17,W43)+COUNTIF('2010 Group Standings'!$K$23,W43)+COUNTIF('2010 Group Standings'!$K$29,W43)+COUNTIF('2010 Group Standings'!$K$35,W43)+COUNTIF('2010 Group Standings'!$K$41,W43)+COUNTIF('2010 Group Standings'!$K$47,W43) -> 1 | Y43: =X43/X$47 -> 0.125
B44: 2 | C44: =COUNTIF('2014 Group Standings'!$K$5,B44)+COUNTIF('2014 Group Standings'!$K$11,B44)+COUNTIF('2014 Group Standings'!$K$17,B44)+COUNTIF('2014 Group Standings'!$K$23,B44)+COUNTIF('2014 Group Standings'!$K$29,B44)+COUNTIF('2014 Group Standings'!$K$35,B44)+COUNTIF('2014 Group Standings'!$K$41,B44)+COUNTIF('2014 Group Standings'!$K$47,B44) -> 3 | D44: =C44/C$47 -> 0.375 | I44: 2 | J44: =COUNTIF('2014 Group Standings'!$K$5,I44)+COUNTIF('2014 Group Standings'!$K$11,I44)+COUNTIF('2014 Group Standings'!$K$17,I44)+COUNTIF('2014 Group Standings'!$K$23,I44)+COUNTIF('2014 Group Standings'!$K$29,I44)+COUNTIF('2014 Group Standings'!$K$35,I44)+COUNTIF('2014 Group Standings'!$K$41,I44)+COUNTIF('2014 Group Standings'!$K$47,I44) -> 3 | K44: =J44/J$47 -> 0.375 | P44: 2 | Q44: =COUNTIF('2010 Group Standings'!$K$5,P44)+COUNTIF('2010 Group Standings'!$K$11,P44)+COUNTIF('2010 Group Standings'!$K$17,P44)+COUNTIF('2010 Group Standings'!$K$23,P44)+COUNTIF('2010 Group Standings'!$K$29,P44)+COUNTIF('2010 Group Standings'!$K$35,P44)+COUNTIF('2010 Group Standings'!$K$41,P44)+COUNTIF('2010 Group Standings'!$K$47,P44) -> 3 | R44: =Q44/Q$47 -> 0.375 | W44: 2 | X44: =COUNTIF('2010 Group Standings'!$K$5,W44)+COUNTIF('2010 Group Standings'!$K$11,W44)+COUNTIF('2010 Group Standings'!$K$17,W44)+COUNTIF('2010 Group Standings'!$K$23,W44)+COUNTIF('2010 Group Standings'!$K$29,W44)+COUNTIF('2010 Group Standings'!$K$35,W44)+COUNTIF('2010 Group Standings'!$K$41,W44)+COUNTIF('2010 Group Standings'!$K$47,W44) -> 3 | Y44: =X44/X$47 -> 0.375
B45: 1 | C45: =COUNTIF('2014 Group Standings'!$K$5,B45)+COUNTIF('2014 Group Standings'!$K$11,B45)+COUNTIF('2014 Group Standings'!$K$17,B45)+COUNTIF('2014 Group Standings'!$K$23,B45)+COUNTIF('2014 Group Standings'!$K$29,B45)+COUNTIF('2014 Group Standings'!$K$35,B45)+COUNTIF('2014 Group Standings'!$K$41,B45)+COUNTIF('2014 Group Standings'!$K$47,B45) -> 2 | D45: =C45/C$47 -> 0.25 | I45: 1 | J45: =COUNTIF('2014 Group Standings'!$K$5,I45)+COUNTIF('2014 Group Standings'!$K$11,I45)+COUNTIF('2014 Group Standings'!$K$17,I45)+COUNTIF('2014 Group Standings'!$K$23,I45)+COUNTIF('2014 Group Standings'!$K$29,I45)+COUNTIF('2014 Group Standings'!$K$35,I45)+COUNTIF('2014 Group Standings'!$K$41,I45)+COUNTIF('2014 Group Standings'!$K$47,I45) -> 2 | K45: =J45/J$47 -> 0.25 | P45: 1 | Q45: =COUNTIF('2010 Group Standings'!$K$5,P45)+COUNTIF('2010 Group Standings'!$K$11,P45)+COUNTIF('2010 Group Standings'!$K$17,P45)+COUNTIF('2010 Group Standings'!$K$23,P45)+COUNTIF('2010 Group Standings'!$K$29,P45)+COUNTIF('2010 Group Standings'!$K$35,P45)+COUNTIF('2010 Group Standings'!$K$41,P45)+COUNTIF('2010 Group Standings'!$K$47,P45) -> 3 | R45: =Q45/Q$47 -> 0.375 | W45: 1 | X45: =COUNTIF('2010 Group Standings'!$K$5,W45)+COUNTIF('2010 Group Standings'!$K$11,W45)+COUNTIF('2010 Group Standings'!$K$17,W45)+COUNTIF('2010 Group Standings'!$K$23,W45)+COUNTIF('2010 Group Standings'!$K$29,W45)+COUNTIF('2010 Group Standings'!$K$35,W45)+COUNTIF('2010 Group Standings'!$K$41,W45)+COUNTIF('2010 Group Standings'!$K$47,W45) -> 3 | Y45: =X45/X$47 -> 0.375
A46: Outsider | B46: 0 | C46: =COUNTIF('2014 Group Standings'!$K$5,B46)+COUNTIF('2014 Group Standings'!$K$11,B46)+COUNTIF('2014 Group Standings'!$K$17,B46)+COUNTIF('2014 Group Standings'!$K$23,B46)+COUNTIF('2014 Group Standings'!$K$29,B46)+COUNTIF('2014 Group Standings'!$K$35,B46)+COUNTIF('2014 Group Standings'!$K$41,B46)+COUNTIF('2014 Group Standings'!$K$47,B46) -> 3 | D46: =C46/C$47 -> 0.375 | H46: Outsider | I46: 0 | J46: =COUNTIF('2014 Group Standings'!$K$5,I46)+COUNTIF('2014 Group Standings'!$K$11,I46)+COUNTIF('2014 Group Standings'!$K$17,I46)+COUNTIF('2014 Group Standings'!$K$23,I46)+COUNTIF('2014 Group Standings'!$K$29,I46)+COUNTIF('2014 Group Standings'!$K$35,I46)+COUNTIF('2014 Group Standings'!$K$41,I46)+COUNTIF('2014 Group Standings'!$K$47,I46) -> 3 | K46: =J46/J$47 -> 0.375 | O46: Outsider | P46: 0 | Q46: =COUNTIF('2010 Group Standings'!$K$5,P46)+COUNTIF('2010 Group Standings'!$K$11,P46)+COUNTIF('2010 Group Standings'!$K$17,P46)+COUNTIF('2010 Group Standings'!$K$23,P46)+COUNTIF('2010 Group Standings'!$K$29,P46)+COUNTIF('2010 Group Standings'!$K$35,P46)+COUNTIF('2010 Group Standings'!$K$41,P46)+COUNTIF('2010 Group Standings'!$K$47,P46) -> 1 | R46: =Q46/Q$47 -> 0.125 | V46: Outsider | W46: 0 | X46: =COUNTIF('2010 Group Standings'!$K$5,W46)+COUNTIF('2010 Group Standings'!$K$11,W46)+COUNTIF('2010 Group Standings'!$K$17,W46)+COUNTIF('2010 Group Standings'!$K$23,W46)+COUNTIF('2010 Group Standings'!$K$29,W46)+COUNTIF('2010 Group Standings'!$K$35,W46)+COUNTIF('2010 Group Standings'!$K$41,W46)+COUNTIF('2010 Group Standings'!$K$47,W46) -> 1 | Y46: =X46/X$47 -> 0.125
A47: Total | C47: =SUM(C43:C46) -> 8 | D47: =SUM(D43:D46) -> 1 | H47: Total | J47: =SUM(J43:J46) -> 8 | K47: =SUM(K43:K46) -> 1 | O47: Total | Q47: =SUM(Q43:Q46) -> 8 | R47: =SUM(R43:R46) -> 1 | V47: Total | X47: =SUM(X43:X46) -> 8 | Y47: =SUM(Y43:Y46) -> 1

Sheet 2018 Group Standings
A1: 2018 | B1: Group Standings
A3: # | B3: Group A | C3: MP | D3: W | E3: D | F3: L | G3: GA | H3: GF | I3: Diff | J3: Pts | K3: Favourites | L3: Strike | M3: % | N3: Outsiders | O3: Strike | P3: %
A4: ? | B4: Russia | C4: =COUNTIFS('All Group Fixtures'!$A$2:$A$2000,$A$1,'All Group Fixtures'!$D$2:$D$2000,$B4)+COUNTIFS('All Group Fixtures'!$A$2:$A$2000,$A$1,'All Group Fixtures'!$E$2:$E$2000,$B4) -> 3 | D4: =COUNTIFS('All Group Fixtures'!$A$2:$A$2000,$A$1,'All Group Fixtures'!$O$2:$O$2000,$B4,'All Group Fixtures'!$D$2:$D$2000,$B4)+COUNTIFS('All Group Fixtures'!$A$2:$A$2000,$A$1,'All Group Fixtures'!$O$2:$O$2000,$B4,'All Group Fixtures'!$E$2:$E$2000,$B4) -> 0 | E4: =COUNTIFS('All Group Fixtures'!$A$2:$A$2000,$A$1,'All Group Fixtures'!$O$2:$O$2000,"Draw",'All Group Fixtures'!$D$2:$D$2000,$B4)+COUNTIFS('All Group Fixtures'!$A$2:$A$2000,$A$1,'All Group Fixtures'!$O$2:$O$2000,"Draw",'All Group Fixtures'!$E$2:$E$2000,$B4) -> 1 | F4: =C4-D4-E4 -> 2 | G4: =SUMIFS('All Group Fixtures'!$F$2:$F$2000,'All Group Fixtures'!$A$2:$A$2000,$A$1,'All Group Fixtures'!$D$2:$D$2000,$B4)+SUMIFS('All Group Fixtures'!$G$2:$G$2000,'All Group Fixtures'!$A$2:$A$2000,$A$1,'All Group Fixtures'!$E$2:$E$2000,$B4) -> 2 | H4: =SUMIFS('All Group Fixtures'!$G$2:$G$2000,'All Group Fixtures'!$A$2:$A$2000,$A$1,'All Group Fixtures'!$D$2:$D$2000,$B4)+SUMIFS('All Group Fixtures'!$F$2:$F$2000,'All Group Fixtures'!$A$2:$A$2000,$A$1,'All Group Fixtures'!$E$2:$E$2000,$B4) -> 2 | I4: =G4-H4 -> 0 | J4: =(D4*3)+(E4*1) -> 1 | K4: =COUNTIFS('All Group Fixtures'!$A$2:$A$2000,$A$1,'All Group Fixtures'!$K$2:$K$2000,$B4) -> 2 | L4: =COUNTIFS('All Group Fixtures'!$A$2:$A$2000,$A$1,'All Group Fixtures'!$K$2:$K$2000,$B4,'All Group Fixtures'!$O$2:$O$2000,$B4) -> 0 | M4: =IF(K4=0,0,L4/K4) -> 0 | N4: =COUNTIFS('All Group Fixtures'!$A$2:$A$2000,$A$1,'All Group Fixtures'!$L$2:$L$2000,$B4) -> 1 | O4: =COUNTIFS('All Group Fixtures'!$A$2:$A$2000,$A$1,'All Group Fixtures'!$L$2:$L$2000,$B4,'All Group Fixtures'!$O$2:$O$2000,$B4) -> 0 | P4: =IF(N4=0,0,O4/N4) -> 0
A5: ? | B5: Saudi Arabia | C5: =COUNTIFS('All Group Fixtures'!$A$2:$A$2000,$A$1,'All Group Fixtures'!$D$2:$D$2000,$B5)+COUNTIFS('All Group Fixtures'!$A$2:$A$2000,$A$1,'All Group Fixtures'!$E$2:$E$2000,$B5) -> 3 | D5: =COUNTIFS('All Group Fixtures'!$A$2:$A$2000,$A$1,'All Group Fixtures'!$O$2:$O$2000,$B5,'All Group Fixtures'!$D$2:$D$2000,$B5)+COUNTIFS('All Group Fixtures'!$A$2:$A$2000,$A$1,'All Group Fixtures'!$O$2:$O$2000,$B5,'All Group Fixtures'!$E$2:$E$2000,$B5) -> 0 | E5: =COUNTIFS('All Group Fixtures'!$A$2:$A$2000,$A$1,'All Group Fixtures'!$O$2:$O$2000,"Draw",'All Group Fixtures'!$D$2:$D$2000,$B5)+COUNTIFS('All Group Fixtures'!$A$2:$A$2000,$A$1,'All Group Fixtures'!$O$2:$O$2000,"Draw",'All Group Fixtures'!$E$2:$E$2000,$B5) -> 1 | F5: =C5-D5-E5 -> 2 | G5: =SUMIFS('All Group Fixtures'!$F$2:$F$2000,'All Group Fixtures'!$A$2:$A$2000,$A$1,'All Group Fixtures'!$D$2:$D$2000,$B5)+SUMIFS('All Group Fixtures'!$G$2:$G$2000,'All Group Fixtures'!$A$2:$A$2000,$A$1,'All Group Fixtures'!$E$2:$E$2000,$B5) -> 2 | H5: =SUMIFS('All Group Fixtures'!$G$2:$G$2000,'All Group Fixtures'!$A$2:$A$2000,$A$1,'All Group Fixtures'!$D$2:$D$2000,$B5)+SUMIFS('All Group Fixtures'!$F$2:$F$2000,'All Group Fixtures'!$A$2:$A$2000,$A$1,'All Group Fixtures'!$E$2:$E$2000,$B5) -> 2 | I5: =G5-H5 -> 0 | J5: =(D5*3)+(E5*1) -> 1 | K5: =COUNTIFS('All Group Fixtures'!$A$2:$A$2000,$A$1,'All Group Fixtures'!$K$2:$K$2000,$B5) -> 0 | L5: =COUNTIFS('All Group Fixtures'!$A$2:$A$2000,$A$1,'All Group Fixtures'!$K$2:$K$2000,$B5,'All Group Fixtures'!$O$2:$O$2000,$B5) -> 0 | M5: =IF(K5=0,0,L5/K5) -> 0 | N5: =COUNTIFS('All Group Fixtures'!$A$2:$A$2000,$A$1,'All Group Fixtures'!$L$2:$L$2000,$B5) -> 3 | O5: =COUNTIFS('All Group Fixtures'!$A$2:$A$2000,$A$1,'All Group Fixtures'!$L$2:$L$2000,$B5,'All Group Fixtures'!$O$2:$O$2000,$B5) -> 0 | P5: =IF(N5=0,0,O5/N5) -> 0
A6: ? | B6: Egypt | C6: =COUNTIFS('All Group Fixtures'!$A$2:$A$2000,$A$1,'All Group Fixtures'!$D$2:$D$2000,$B6)+COUNTIFS('All Group Fixtures'!$A$2:$A$2000,$A$1,'All Group Fixtures'!$E$2:$E$2000,$B6) -> 3 | D6: =COUNTIFS('All Group Fixtures'!$A$2:$A$2000,$A$1,'All Group Fixtures'!$O$2:$O$2000,$B6,'All Group Fixtures'!$D$2:$D$2000,$B6)+COUNTIFS('All Group Fixtures'!$A$2:$A$2000,$A$1,'All Group Fixtures'!$O$2:$O$2000,$B6,'All Group Fixtures'!$E$2:$E$2000,$B6) -> 0 | E6: =COUNTIFS('All Group Fixtures'!$A$2:$A$2000,$A$1,'All Group Fixtures'!$O$2:$O$2000,"Draw",'All Group Fixtures'!$D$2:$D$2000,$B6)+COUNTIFS('All Group Fixtures'!$A$2:$A$2000,$A$1,'All Group Fixtures'!$O$2:$O$2000,"Draw",'All Group Fixtures'!$E$2:$E$2000,$B6) -> 0 | F6: =C6-D6-E6 -> 3 | G6: =SUMIFS('All Group Fixtures'!$F$2:$F$2000,'All Group Fixtures'!$A$2:$A$2000,$A$1,'All Group Fixtures'!$D$2:$D$2000,$B6)+SUMIFS('All Group Fixtures'!$G$2:$G$2000,'All Group Fixtures'!$A$2:$A$2000,$A$1,'All Group Fixtures'!$E$2:$E$2000,$B6) -> 0 | H6: =SUMIFS('All Group Fixtures'!$G$2:$G$2000,'All Group Fixtures'!$A$2:$A$2000,$A$1,'All Group Fixtures'!$D$2:$D$2000,$B6)+SUMIFS('All Group Fixtures'!$F$2:$F$2000,'All Group Fixtures'!$A$2:$A$2000,$A$1,'All Group Fixtures'!$E$2:$E$2000,$B6) -> 0 | I6: =G6-H6 -> 0 | J6: =(D6*3)+(E6*1) -> 0 | K6: =COUNTIFS('All Group Fixtures'!$A$2:$A$2000,$A$1,'All Group Fixtures'!$K$2:$K$2000,$B6) -> 1 | L6: =COUNTIFS('All Group Fixtures'!$A$2:$A$2000,$A$1,'All Group Fixtures'!$K$2:$K$2000,$B6,'All Group Fixtures'!$O$2:$O$2000,$B6) -> 0 | M6: =IF(K6=0,0,L6/K6) -> 0 | N6: =COUNTIFS('All Group Fixtures'!$A$2:$A$2000,$A$1,'All Group Fixtures'!$L$2:$L$2000,$B6) -> 2 | O6: =COUNTIFS('All Group Fixtures'!$A$2:$A$2000,$A$1,'All Group Fixtures'!$L$2:$L$2000,$B6,'All Group Fixtures'!$O$2:$O$2000,$B6) -> 0 | P6: =IF(N6=0,0,O6/N6) -> 0
A7: ? | B7: Uruguay | C7: =COUNTIFS('All Group Fixtures'!$A$2:$A$2000,$A$1,'All Group Fixtures'!$D$2:$D$2000,$B7)+COUNTIFS('All Group Fixtures'!$A$2:$A$2000,$A$1,'All Group Fixtures'!$E$2:$E$2000,$B7) -> 3 | D7: =COUNTIFS('All Group Fixtures'!$A$2:$A$2000,$A$1,'All Group Fixtures'!$O$2:$O$2000,$B7,'All Group Fixtures'!$D$2:$D$2000,$B7)+COUNTIFS('All Group Fixtures'!$A$2:$A$2000,$A$1,'All Group Fixtures'!$O$2:$O$2000,$B7,'All Group Fixtures'!$E$2:$E$2000,$B7) -> 0 | E7: =COUNTIFS('All Group Fixtures'!$A$2:$A$2000,$A$1,'All Group Fixtures'!$O$2:$O$2000,"Draw",'All Group Fixtures'!$D$2:$D$2000,$B7)+COUNTIFS('All Group Fixtures'!$A$2:$A$2000,$A$1,'All Group Fixtures'!$O$2:$O$2000,"Draw",'All Group Fixtures'!$E$2:$E$2000,$B7) -> 0 | F7: =C7-D7-E7 -> 3 | G7: =SUMIFS('All Group Fixtures'!$F$2:$F$2000,'All Group Fixtures'!$A$2:$A$2000,$A$1,'All Group Fixtures'!$D$2:$D$2000,$B7)+SUMIFS('All Group Fixtures'!$G$2:$G$2000,'All Group Fixtures'!$A$2:$A$2000,$A$1,'All Group Fixtures'!$E$2:$E$2000,$B7) -> 0 | H7: =SUMIFS('All Group Fixtures'!$G$2:$G$2000,'All Group Fixtures'!$A$2:$A$2000,$A$1,'All Group Fixtures'!$D$2:$D$2000,$B7)+SUMIFS('All Group Fixtures'!$F$2:$F$2000,'All Group Fixtures'!$A$2:$A$2000,$A$1,'All Group Fixtures'!$E$2:$E$2000,$B7) -> 0 | I7: =G7-H7 -> 0 | J7: =(D7*3)+(E7*1) -> 0 | K7: =COUNTIFS('All Group Fixtures'!$A$2:$A$2000,$A$1,'All Group Fixtures'!$K$2:$K$2000,$B7) -> 3 | L7: =COUNTIFS('All Group Fixtures'!$A$2:$A$2000,$A$1,'All Group Fixtures'!$K$2:$K$2000,$B7,'All Group Fixtures'!$O$2:$O$2000,$B7) -> 0 | M7: =IF(K7=0,0,L7/K7) -> 0 | N7: =COUNTIFS('All Group Fixtures'!$A$2:$A$2000,$A$1,'All Group Fixtures'!$L$2:$L$2000,$B7) -> 0 | O7: =COUNTIFS('All Group Fixtures'!$A$2:$A$2000,$A$1,'All Group Fixtures'!$L$2:$L$2000,$B7,'All Group Fixtures'!$O$2:$O$2000,$B7) -> 0 | P7: =IF(N7=0,0,O7/N7) -> 0
A9: # | B9: Group B | C9: MP | D9: W | E9: D | F9: L | G9: GA | H9: GF | I9: Diff | J9: Pts | K9: Favourites | L9: Strike | M9: % | N9: Outsiders | O9: Strike | P9: %
A10: ? | B10: Portugal | C10: =COUNTIFS('All Group Fixtures'!$A$2:$A$2000,$A$1,'All Group Fixtures'!$D$2:$D$2000,$B10)+COUNTIFS('All Group Fixtures'!$A$2:$A$2000,$A$1,'All Group Fixtures'!$E$2:$E$2000,$B10) -> 3 | D10: =COUNTIFS('All Group Fixtures'!$A$2:$A$2000,$A$1,'All Group Fixtures'!$O$2:$O$2000,$B10,'All Group Fixtures'!$D$2:$D$2000,$B10)+COUNTIFS('All Group Fixtures'!$A$2:$A$2000,$A$1,'All Group Fixtures'!$O$2:$O$2000,$B10,'All Group Fixtures'!$E$2:$E$2000,$B10) -> 0 | E10: =COUNTIFS('All Group Fixtures'!$A$2:$A$2000,$A$1,'All Group Fixtures'!$O$2:$O$2000,"Draw",'All Group Fixtures'!$D$2:$D$2000,$B10)+COUNTIFS('All Group Fixtures'!$A$2:$A$2000,$A$1,'All Group Fixtures'!$O$2:$O$2000,"Draw",'All Group Fixtures'!$E$2:$E$2000,$B10) -> 0 | F10: =C10-D10-E10 -> 3 | G10: =SUMIFS('All Group Fixtures'!$F$2:$F$2000,'All Group Fixtures'!$A$2:$A$2000,$A$1,'All Group Fixtures'!$D$2:$D$2000,$B10)+SUMIFS('All Group Fixtures'!$G$2:$G$2000,'All Group Fixtures'!$A$2:$A$2000,$A$1,'All Group Fixtures'!$E$2:$E$2000,$B10) -> 0 | H10: =SUMIFS('All Group Fixtures'!$G$2:$G$2000,'All Group Fixtures'!$A$2:$A$2000,$A$1,'All Group Fixtures'!$D$2:$D$2000,$B10)+SUMIFS('All Group Fixtures'!$F$2:$F$2000,'All Group Fixtures'!$A$2:$A$2000,$A$1,'All Group Fixtures'!$E$2:$E$2000,$B10) -> 0 | I10: =G10-H10 -> 0 | J10: =(D10*3)+(E10*1) -> 0 | K10: =COUNTIFS('All Group Fixtures'!$A$2:$A$2000,$A$1,'All Group Fixtures'!$K$2:$K$2000,$B10) -> 2 | L10: =COUNTIFS('All Group Fixtures'!$A$2:$A$2000,$A$1,'All Group Fixtures'!$K$2:$K$2000,$B10,'All Group Fixtures'!$O$2:$O$2000,$B10) -> 0 | M10: =IF(K10=0,0,L10/K10) -> 0 | N10: =COUNTIFS('All Group Fixtures'!$A$2:$A$2000,$A$1,'All Group Fixtures'!$L$2:$L$2000,$B10) -> 1 | O10: =COUNTIFS('All Group Fixtures'!$A$2:$A$2000,$A$1,'All Group Fixtures'!$L$2:$L$2000,$B10,'All Group Fixtures'!$O$2:$O$2000,$B10) -> 0 | P10: =IF(N10=0,0,O10/N10) -> 0
A11: ? | B11: Spain | C11: =COUNTIFS('All Group Fixtures'!$A$2:$A$2000,$A$1,'All Group Fixtures'!$D$2:$D$2000,$B11)+COUNTIFS('All Group Fixtures'!$A$2:$A$2000,$A$1,'All Group Fixtures'!$E$2:$E$2000,$B11) -> 3 | D11: =COUNTIFS('All Group Fixtures'!$A$2:$A$2000,$A$1,'All Group Fixtures'!$O$2:$O$2000,$B11,'All Group Fixtures'!$D$2:$D$2000,$B11)+COUNTIFS('All Group Fixtures'!$A$2:$A$2000,$A$1,'All Group Fixtures'!$O$2:$O$2000,$B11,'All Group Fixtures'!$E$2:$E$2000,$B11) -> 0 | E11: =COUNTIFS('All Group Fixtures'!$A$2:$A$2000,$A$1,'All Group Fixtures'!$O$2:$O$2000,"Draw",'All Group Fixtures'!$D$2:$D$2000,$B11)+COUNTIFS('All Group Fixtures'!$A$2:$A$2000,$A$1,'All Group Fixtures'!$O$2:$O$2000,"Draw",'All Group Fixtures'!$E$2:$E$2000,$B11) -> 0 | F11: =C11-D11-E11 -> 3 | G11: =SUMIFS('All Group Fixtures'!$F$2:$F$2000,'All Group Fixtures'!$A$2:$A$2000,$A$1,'All Group Fixtures'!$D$2:$D$2000,$B11)+SUMIFS('All Group Fixtures'!$G$2:$G$2000,'All Group Fixtures'!$A$2:$A$2000,$A$1,'All Group Fixtures'!$E$2:$E$2000,$B11) -> 0 | H11: =SUMIFS('All Group Fixtures'!$G$2:$G$2000,'All Group Fixtures'!$A$2:$A$2000,$A$1,'All Group Fixtures'!$D$2:$D$2000,$B11)+SUMIFS('All Group Fixtures'!$F$2:$F$2000,'All Group Fixtures'!$A$2:$A$2000,$A$1,'All Group Fixtures'!$E$2:$E$2000,$B11) -> 0 | I11: =G11-H11 -> 0 | J11: =(D11*3)+(E11*1) -> 0 | K11: =COUNTIFS('All Group Fixtures'!$A$2:$A$2000,$A$1,'All Group Fixtures'!$K$2:$K$2000,$B11) -> 3 | L11: =COUNTIFS('All Group Fixtures'!$A$2:$A$2000,$A$1,'All Group Fixtures'!$K$2:$K$2000,$B11,'All Group Fixtures'!$O$2:$O$2000,$B11) -> 0 | M11: =IF(K11=0,0,L11/K11) -> 0 | N11: =COUNTIFS('All Group Fixtures'!$A$2:$A$2000,$A$1,'All Group Fixtures'!$L$2:$L$2000,$B11) -> 0 | O11: =COUNTIFS('All Group Fixtures'!$A$2:$A$2000,$A$1,'All Group Fixtures'!$L$2:$L$2000,$B11,'All Group Fixtures'!$O$2:$O$2000,$B11) -> 0 | P11: =IF(N11=0,0,O11/N11) -> 0
A12: ? | B12: Morocco | C12: =COUNTIFS('All Group Fixtures'!$A$2:$A$2000,$A$1,'All Group Fixtures'!$D$2:$D$2000,$B12)+COUNTIFS('All Group Fixtures'!$A$2:$A$2000,$A$1,'All Group Fixtures'!$E$2:$E$2000,$B12) -> 3 | D12: =COUNTIFS('All Group Fixtures'!$A$2:$A$2000,$A$1,'All Group Fixtures'!$O$2:$O$2000,$B12,'All Group Fixtures'!$D$2:$D$2000,$B12)+COUNTIFS('All Group Fixtures'!$A$2:$A$2000,$A$1,'All Group Fixtures'!$O$2:$O$2000,$B12,'All Group Fixtures'!$E$2:$E$2000,$B12) -> 0 | E12: =COUNTIFS('All Group Fixtures'!$A$2:$A$2000,$A$1,'All Group Fixtures'!$O$2:$O$2000,"Draw",'All Group Fixtures'!$D$2:$D$2000,$B12)+COUNTIFS('All Group Fixtures'!$A$2:$A$2000,$A$1,'All Group Fixtures'!$O$2:$O$2000,"Draw",'All Group Fixtures'!$E$2:$E$2000,$B12) -> 0 | F12: =C12-D12-E12 -> 3 | G12: =SUMIFS('All Group Fixtures'!$F$2:$F$2000,'All Group Fixtures'!$A$2:$A$2000,$A$1,'All Group Fixtures'!$D$2:$D$2000,$B12)+SUMIFS('All Group Fixtures'!$G$2:$G$2000,'All Group Fixtures'!$A$2:$A$2000,$A$1,'All Group Fixtures'!$E$2:$E$2000,$B12) -> 0 | H12: =SUMIFS('All Group Fixtures'!$G$2:$G$2000,'All Group Fixtures'!$A$2:$A$2000,$A$1,'All Group Fixtures'!$D$2:$D$2000,$B12)+SUMIFS('All Group Fixtures'!$F$2:$F$2000,'All Group Fixtures'!$A$2:$A$2000,$A$1,'All Group Fixtures'!$E$2:$E$2000,$B12) -> 0 | I12: =G12-H12 -> 0 | J12: =(D12*3)+(E12*1) -> 0 | K12: =COUNTIFS('All Group Fixtures'!$A$2:$A$2000,$A$1,'All Group Fixtures'!$K$2:$K$2000,$B12) -> 1 | L12: =COUNTIFS('All Group Fixtures'!$A$2:$A$2000,$A$1,'All Group Fixtures'!$K$2:$K$2000,$B12,'All Group Fixtures'!$O$2:$O$2000,$B12) -> 0 | M12: =IF(K12=0,0,L12/K12) -> 0 | N12: =COUNTIFS('All Group Fixtures'!$A$2:$A$2000,$A$1,'All Group Fixtures'!$L$2:$L$2000,$B12) -> 2 | O12: =COUNTIFS('All Group Fixtures'!$A$2:$A$2000,$A$1,'All Group Fixtures'!$L$2:$L$2000,$B12,'All Group Fixtures'!$O$2:$O$2000,$B12) -> 0 | P12: =IF(N12=0,0,O12/N12) -> 0
A13: ? | B13: Iran | C13: =COUNTIFS('All Group Fixtures'!$A$2:$A$2000,$A$1,'All Group Fixtures'!$D$2:$D$2000,$B13)+COUNTIFS('All Group Fixtures'!$A$2:$A$2000,$A$1,'All Group Fixtures'!$E$2:$E$2000,$B13) -> 3 | D13: =COUNTIFS('All Group Fixtures'!$A$2:$A$2000,$A$1,'All Group Fixtures'!$O$2:$O$2000,$B13,'All Group Fixtures'!$D$2:$D$2000,$B13)+COUNTIFS('All Group Fixtures'!$A$2:$A$2000,$A$1,'All Group Fixtures'!$O$2:$O$2000,$B13,'All Group Fixtures'!$E$2:$E$2000,$B13) -> 0 | E13: =COUNTIFS('All Group Fixtures'!$A$2:$A$2000,$A$1,'All Group Fixtures'!$O$2:$O$2000,"Draw",'All Group Fixtures'!$D$2:$D$2000,$B13)+COUNTIFS('All Group Fixtures'!$A$2:$A$2000,$A$1,'All Group Fixtures'!$O$2:$O$2000,"Draw",'All Group Fixtures'!$E$2:$E$2000,$B13) -> 0 | F13: =C13-D13-E13 -> 3 | G13: =SUMIFS('All Group Fixtures'!$F$2:$F$2000,'All Group Fixtures'!$A$2:$A$2000,$A$1,'All Group Fixtures'!$D$2:$D$2000,$B13)+SUMIFS('All Group Fixtures'!$G$2:$G$2000,'All Group Fixtures'!$A$2:$A$2000,$A$1,'All Group Fixtures'!$E$2:$E$2000,$B13) -> 0 | H13: =SUMIFS('All Group Fixtures'!$G$2:$G$2000,'All Group Fixtures'!$A$2:$A$2000,$A$1,'All Group Fixtures'!$D$2:$D$2000,$B13)+SUMIFS('All Group Fixtures'!$F$2:$F$2000,'All Group Fixtures'!$A$2:$A$2000,$A$1,'All Group Fixtures'!$E$2:$E$2000,$B13) -> 0 | I13: =G13-H13 -> 0 | J13: =(D13*3)+(E13*1) -> 0 | K13: =COUNTIFS('All Group Fixtures'!$A$2:$A$2000,$A$1,'All Group Fixtures'!$K$2:$K$2000,$B13) -> 0 | L13: =COUNTIFS('All Group Fixtures'!$A$2:$A$2000,$A$1,'All Group Fixtures'!$K$2:$K$2000,$B13,'All Group Fixtures'!$O$2:$O$2000,$B13) -> 0 | M13: =IF(K13=0,0,L13/K13) -> 0 | N13: =COUNTIFS('All Group Fixtures'!$A$2:$A$2000,$A$1,'All Group Fixtures'!$L$2:$L$2000,$B13) -> 3 | O13: =COUNTIFS('All Group Fixtures'!$A$2:$A$2000,$A$1,'All Group Fixtures'!$L$2:$L$2000,$B13,'All Group Fixtures'!$O$2:$O$2000,$B13) -> 0 | P13: =IF(N13=0,0,O13/N13) -> 0
A15: # | B15: Group C | C15: MP | D15: W | E15: D | F15: L | G15: GA | H15: GF | I15: Diff | J15: Pts | K15: Favourites | L15: Strike | M15: % | N15: Outsiders | O15: Strike | P15: %
A16: ? | B16: France | C16: =COUNTIFS('All Group Fixtures'!$A$2:$A$2000,$A$1,'All Group Fixtures'!$D$2:$D$2000,$B16)+COUNTIFS('All Group Fixtures'!$A$2:$A$2000,$A$1,'All Group Fixtures'!$E$2:$E$2000,$B16) -> 3 | D16: =COUNTIFS('All Group Fixtures'!$A$2:$A$2000,$A$1,'All Group Fixtures'!$O$2:$O$2000,$B16,'All Group Fixtures'!$D$2:$D$2000,$B16)+COUNTIFS('All Group Fixtures'!$A$2:$A$2000,$A$1,'All Group Fixtures'!$O$2:$O$2000,$B16,'All Group Fixtures'!$E$2:$E$2000,$B16) -> 0 | E16: =COUNTIFS('All Group Fixtures'!$A$2:$A$2000,$A$1,'All Group Fixtures'!$O$2:$O$2000,"Draw",'All Group Fixtures'!$D$2:$D$2000,$B16)+COUNTIFS('All Group Fixtures'!$A$2:$A$2000,$A$1,'All Group Fixtures'!$O$2:$O$2000,"Draw",'All Group Fixtures'!$E$2:$E$2000,$B16) -> 0 | F16: =C16-D16-E16 -> 3 | G16: =SUMIFS('All Group Fixtures'!$F$2:$F$2000,'All Group Fixtures'!$A$2:$A$2000,$A$1,'All Group Fixtures'!$D$2:$D$2000,$B16)+SUMIFS('All Group Fixtures'!$G$2:$G$2000,'All Group Fixtures'!$A$2:$A$2000,$A$1,'All Group Fixtures'!$E$2:$E$2000,$B16) -> 0 | H16: =SUMIFS('All Group Fixtures'!$G$2:$G$2000,'All Group Fixtures'!$A$2:$A$2000,$A$1,'All Group Fixtures'!$D$2:$D$2000,$B16)+SUMIFS('All Group Fixtures'!$F$2:$F$2000,'All Group Fixtures'!$A$2:$A$2000,$A$1,'All Group Fixtures'!$E$2:$E$2000,$B16) -> 0 | I16: =G16-H16 -> 0 | J16: =(D16*3)+(E16*1) -> 0 | K16: =COUNTIFS('All Group Fixtures'!$A$2:$A$2000,$A$1,'All Group Fixtures'!$K$2:$K$2000,$B16) -> 3 | L16: =COUNTIFS('All Group Fixtures'!$A$2:$A$2000,$A$1,'All Group Fixtures'!$K$2:$K$2000,$B16,'All Group Fixtures'!$O$2:$O$2000,$B16) -> 0 | M16: =IF(K16=0,0,L16/K16) -> 0 | N16: =COUNTIFS('All Group Fixtures'!$A$2:$A$2000,$A$1,'All Group Fixtures'!$L$2:$L$2000,$B16) -> 0 | O16: =COUNTIFS('All Group Fixtures'!$A$2:$A$2000,$A$1,'All Group Fixtures'!$L$2:$L$2000,$B16,'All Group Fixtures'!$O$2:$O$2000,$B16) -> 0 | P16: =IF(N16=0,0,O16/N16) -> 0
A17: ? | B17: Australia | C17: =COUNTIFS('All Group Fixtures'!$A$2:$A$2000,$A$1,'All Group Fixtures'!$D$2:$D$2000,$B17)+COUNTIFS('All Group Fixtures'!$A$2:$A$2000,$A$1,'All Group Fixtures'!$E$2:$E$2000,$B17) -> 3 | D17: =COUNTIFS('All Group Fixtures'!$A$2:$A$2000,$A$1,'All Group Fixtures'!$O$2:$O$2000,$B17,'All Group Fixtures'!$D$2:$D$2000,$B17)+COUNTIFS('All Group Fixtures'!$A$2:$A$2000,$A$1,'All Group Fixtures'!$O$2:$O$2000,$B17,'All Group Fixtures'!$E$2:$E$2000,$B17) -> 0 | E17: =COUNTIFS('All Group Fixtures'!$A$2:$A$2000,$A$1,'All Group Fixtures'!$O$2:$O$2000,"Draw",'All Group Fixtures'!$D$2:$D$2000,$B17)+COUNTIFS('All Group Fixtures'!$A$2:$A$2000,$A$1,'All Group Fixtures'!$O$2:$O$2000,"Draw",'All Group Fixtures'!$E$2:$E$2000,$B17) -> 0 | F17: =C17-D17-E17 -> 3 | G17: =SUMIFS('All Group Fixtures'!$F$2:$F$2000,'All Group Fixtures'!$A$2:$A$2000,$A$1,'All Group Fixtures'!$D$2:$D$2000,$B17)+SUMIFS('All Group Fixtures'!$G$2:$G$2000,'All Group Fixtures'!$A$2:$A$2000,$A$1,'All Group Fixtures'!$E$2:$E$2000,$B17) -> 0 | H17: =SUMIFS('All Group Fixtures'!$G$2:$G$2000,'All Group Fixtures'!$A$2:$A$2000,$A$1,'All Group Fixtures'!$D$2:$D$2000,$B17)+SUMIFS('All Group Fixtures'!$F$2:$F$2000,'All Group Fixtures'!$A$2:$A$2000,$A$1,'All Group Fixtures'!$E$2:$E$2000,$B17) -> 0 | I17: =G17-H17 -> 0 | J17: =(D17*3)+(E17*1) -> 0 | K17: =COUNTIFS('All Group Fixtures'!$A$2:$A$2000,$A$1,'All Group Fixtures'!$K$2:$K$2000,$B17) -> 0 | L17: =COUNTIFS('All Group Fixtures'!$A$2:$A$2000,$A$1,'All Group Fixtures'!$K$2:$K$2000,$B17,'All Group Fixtures'!$O$2:$O$2000,$B17) -> 0 | M17: =IF(K17=0,0,L17/K17) -> 0 | N17: =COUNTIFS('All Group Fixtures'!$A$2:$A$2000,$A$1,'All Group Fixtures'!$L$2:$L$2000,$B17) -> 3 | O17: =COUNTIFS('All Group Fixtures'!$A$2:$A$2000,$A$1,'All Group Fixtures'!$L$2:$L$2000,$B17,'All Group Fixtures'!$O$2:$O$2000,$B17) -> 0 | P17: =IF(N17=0,0,O17/N17) -> 0
A18: ? | B18: Peru | C18: =COUNTIFS('All Group Fixtures'!$A$2:$A$2000,$A$1,'All Group Fixtures'!$D$2:$D$2000,$B18)+COUNTIFS('All Group Fixtures'!$A$2:$A$2000,$A$1,'All Group Fixtures'!$E$2:$E$2000,$B18) -> 3 | D18: =COUNTIFS('All Group Fixtures'!$A$2:$A$2000,$A$1,'All Group Fixtures'!$O$2:$O$2000,$B18,'All Group Fixtures'!$D$2:$D$2000,$B18)+COUNTIFS('All Group Fixtures'!$A$2:$A$2000,$A$1,'All Group Fixtures'!$O$2:$O$2000,$B18,'All Group Fixtures'!$E$2:$E$2000,$B18) -> 0 | E18: =COUNTIFS('All Group Fixtures'!$A$2:$A$2000,$A$1,'All Group Fixtures'!$O$2:$O$2000,"Draw",'All Group Fixtures'!$D$2:$D$2000,$B18)+COUNTIFS('All Group Fixtures'!$A$2:$A$2000,$A$1,'All Group Fixtures'!$O$2:$O$2000,"Draw",'All Group Fixtures'!$E$2:$E$2000,$B18) -> 0 | F18: =C18-D18-E18 -> 3 | G18: =SUMIFS('All Group Fixtures'!$F$2:$F$2000,'All Group Fixtures'!$A$2:$A$2000,$A$1,'All Group Fixtures'!$D$2:$D$2000,$B18)+SUMIFS('All Group Fixtures'!$G$2:$G$2000,'All Group Fixtures'!$A$2:$A$2000,$A$1,'All Group Fixtures'!$E$2:$E$2000,$B18) -> 0 | H18: =SUMIFS('All Group Fixtures'!$G$2:$G$2000,'All Group Fixtures'!$A$2:$A$2000,$A$1,'All Group Fixtures'!$D$2:$D$2000,$B18)+SUMIFS('All Group Fixtures'!$F$2:$F$2000,'All Group Fixtures'!$A$2:$A$2000,$A$1,'All Group Fixtures'!$E$2:$E$2000,$B18) -> 0 | I18: =G18-H18 -> 0 | J18: =(D18*3)+(E18*1) -> 0 | K18: =COUNTIFS('All Group Fixtures'!$A$2:$A$2000,$A$1,'All Group Fixtures'!$K$2:$K$2000,$B18) -> 1 | L18: =COUNTIFS('All Group Fixtures'!$A$2:$A$2000,$A$1,'All Group Fixtures'!$K$2:$K$2000,$B18,'All Group Fixtures'!$O$2:$O$2000,$B18) -> 0 | M18: =IF(K18=0,0,L18/K18) -> 0 | N18: =COUNTIFS('All Group Fixtures'!$A$2:$A$2000,$A$1,'All Group Fixtures'!$L$2:$L$2000,$B18) -> 2 | O18: =COUNTIFS('All Group Fixtures'!$A$2:$A$2000,$A$1,'All Group Fixtures'!$L$2:$L$2000,$B18,'All Group Fixtures'!$O$2:$O$2000,$B18) -> 0 | P18: =IF(N18=0,0,O18/N18) -> 0
A19: ? | B19: Denmark | C19: =COUNTIFS('All Group Fixtures'!$A$2:$A$2000,$A$1,'All Group Fixtures'!$D$2:$D$2000,$B19)+COUNTIFS('All Group Fixtures'!$A$2:$A$2000,$A$1,'All Group Fixtures'!$E$2:$E$2000,$B19) -> 3 | D19: =COUNTIFS('All Group Fixtures'!$A$2:$A$2000,$A$1,'All Group Fixtures'!$O$2:$O$2000,$B19,'All Group Fixtures'!$D$2:$D$2000,$B19)+COUNTIFS('All Group Fixtures'!$A$2:$A$2000,$A$1,'All Group Fixtures'!$O$2:$O$2000,$B19,'All Group Fixtures'!$E$2:$E$2000,$B19) -> 0 | E19: =COUNTIFS('All Group Fixtures'!$A$2:$A$2000,$A$1,'All Group Fixtures'!$O$2:$O$2000,"Draw",'All Group Fixtures'!$D$2:$D$2000,$B19)+COUNTIFS('All Group Fixtures'!$A$2:$A$2000,$A$1,'All Group Fixtures'!$O$2:$O$2000,"Draw",'All Group Fixtures'!$E$2:$E$2000,$B19) -> 0 | F19: =C19-D19-E19 -> 3 | G19: =SUMIFS('All Group Fixtures'!$F$2:$F$2000,'All Group Fixtures'!$A$2:$A$2000,$A$1,'All Group Fixtures'!$D$2:$D$2000,$B19)+SUMIFS('All Group Fixtures'!$G$2:$G$2000,'All Group Fixtures'!$A$2:$A$2000,$A$1,'All Group Fixtures'!$E$2:$E$2000,$B19) -> 0 | H19: =SUMIFS('All Group Fixtures'!$G$2:$G$2000,'All Group Fixtures'!$A$2:$A$2000,$A$1,'All Group Fixtures'!$D$2:$D$2000,$B19)+SUMIFS('All Group Fixtures'!$F$2:$F$2000,'All Group Fixtures'!$A$2:$A$2000,$A$1,'All Group Fixtures'!$E$2:$E$2000,$B19) -> 0 | I19: =G19-H19 -> 0 | J19: =(D19*3)+(E19*1) -> 0 | K19: =COUNTIFS('All Group Fixtures'!$A$2:$A$2000,$A$1,'All Group Fixtures'!$K$2:$K$2000,$B19) -> 2 | L19: =COUNTIFS('All Group Fixtures'!$A$2:$A$2000,$A$1,'All Group Fixtures'!$K$2:$K$2000,$B19,'All Group Fixtures'!$O$2:$O$2000,$B19) -> 0 | M19: =IF(K19=0,0,L19/K19) -> 0 | N19: =COUNTIFS('All Group Fixtures'!$A$2:$A$2000,$A$1,'All Group Fixtures'!$L$2:$L$2000,$B19) -> 1 | O19: =COUNTIFS('All Group Fixtures'!$A$2:$A$2000,$A$1,'All Group Fixtures'!$L$2:$L$2000,$B19,'All Group Fixtures'!$O$2:$O$2000,$B19) -> 0 | P19: =IF(N19=0,0,O19/N19) -> 0
A21: # | B21: Group D | C21: MP | D21: W | E21: D | F21: L | G21: GA | H21: GF | I21: Diff | J21: Pts | K21: Favourites | L21: Strike | M21: % | N21: Outsiders | O21: Strike | P21: %
A22: ? | B22: Argentina | C22: =COUNTIFS('All Group Fixtures'!$A$2:$A$2000,$A$1,'All Group Fixtures'!$D$2:$D$2000,$B22)+COUNTIFS('All Group Fixtures'!$A$2:$A$2000,$A$1,'All Group Fixtures'!$E$2:$E$2000,$B22) -> 3 | D22: =COUNTIFS('All Group Fixtures'!$A$2:$A$2000,$A$1,'All Group Fixtures'!$O$2:$O$2000,$B22,'All Group Fixtures'!$D$2:$D$2000,$B22)+COUNTIFS('All Group Fixtures'!$A$2:$A$2000,$A$1,'All Group Fixtures'!$O$2:$O$2000,$B22,'All Group Fixtures'!$E$2:$E$2000,$B22) -> 0 | E22: =COUNTIFS('All Group Fixtures'!$A$2:$A$2000,$A$1,'All Group Fixtures'!$O$2:$O$2000,"Draw",'All Group Fixtures'!$D$2:$D$2000,$B22)+COUNTIFS('All Group Fixtures'!$A$2:$A$2000,$A$1,'All Group Fixtures'!$O$2:$O$2000,"Draw",'All Group Fixtures'!$E$2:$E$2000,$B22) -> 0 | F22: =C22-D22-E22 -> 3 | G22: =SUMIFS('All Group Fixtures'!$F$2:$F$2000,'All Group Fixtures'!$A$2:$A$2000,$A$1,'All Group Fixtures'!$D$2:$D$2000,$B22)+SUMIFS('All Group Fixtures'!$G$2:$G$2000,'All Group Fixtures'!$A$2:$A$2000,$A$1,'All Group Fixtures'!$E$2:$E$2000,$B22) -> 0 | H22: =SUMIFS('All Group Fixtures'!$G$2:$G$2000,'All Group Fixtures'!$A$2:$A$2000,$A$1,'All Group Fixtures'!$D$2:$D$2000,$B22)+SUMIFS('All Group Fixtures'!$F$2:$F$2000,'All Group Fixtures'!$A$2:$A$2000,$A$1,'All Group Fixtures'!$E$2:$E$2000,$B22) -> 0 | I22: =G22-H22 -> 0 | J22: =(D22*3)+(E22*1) -> 0 | K22: =COUNTIFS('All Group Fixtures'!$A$2:$A$2000,$A$1,'All Group Fixtures'!$K$2:$K$2000,$B22) -> 3 | L22: =COUNTIFS('All Group Fixtures'!$A$2:$A$2000,$A$1,'All Group Fixtures'!$K$2:$K$2000,$B22,'All Group Fixtures'!$O$2:$O$2000,$B22) -> 0 | M22: =IF(K22=0,0,L22/K22) -> 0 | N22: =COUNTIFS('All Group Fixtures'!$A$2:$A$2000,$A$1,'All Group Fixtures'!$L$2:$L$2000,$B22) -> 0 | O22: =COUNTIFS('All Group Fixtures'!$A$2:$A$2000,$A$1,'All Group Fixtures'!$L$2:$L$2000,$B22,'All Group Fixtures'!$O$2:$O$2000,$B22) -> 0 | P22: =IF(N22=0,0,O22/N22) -> 0
A23: ? | B23: Iceland | C23: =COUNTIFS('All Group Fixtures'!$A$2:$A$2000,$A$1,'All Group Fixtures'!$D$2:$D$2000,$B23)+COUNTIFS('All Group Fixtures'!$A$2:$A$2000,$A$1,'All Group Fixtures'!$E$2:$E$2000,$B23) -> 3 | D23: =COUNTIFS('All Group Fixtures'!$A$2:$A$2000,$A$1,'All Group Fixtures'!$O$2:$O$2000,$B23,'All Group Fixtures'!$D$2:$D$2000,$B23)+COUNTIFS('All Group Fixtures'!$A$2:$A$2000,$A$1,'All Group Fixtures'!$O$2:$O$2000,$B23,'All Group Fixtures'!$E$2:$E$2000,$B23) -> 0 | E23: =COUNTIFS('All Group Fixtures'!$A$2:$A$2000,$A$1,'All Group Fixtures'!$O$2:$O$2000,"Draw",'All Group Fixtures'!$D$2:$D$2000,$B23)+COUNTIFS('All Group Fixtures'!$A$2:$A$2000,$A$1,'All Group Fixtures'!$O$2:$O$2000,"Draw",'All Group Fixtures'!$E$2:$E$2000,$B23) -> 0 | F23: =C23-D23-E23 -> 3 | G23: =SUMIFS('All Group Fixtures'!$F$2:$F$2000,'All Group Fixtures'!$A$2:$A$2000,$A$1,'All Group Fixtures'!$D$2:$D$2000,$B23)+SUMIFS('All Group Fixtures'!$G$2:$G$2000,'All Group Fixtures'!$A$2:$A$2000,$A$1,'All Group Fixtures'!$E$2:$E$2000,$B23) -> 0 | H23: =SUMIFS('All Group Fixtures'!$G$2:$G$2000,'All Group Fixtures'!$A$2:$A$2000,$A$1,'All Group Fixtures'!$D$2:$D$2000,$B23)+SUMIFS('All Group Fixtures'!$F$2:$F$2000,'All Group Fixtures'!$A$2:$A$2000,$A$1,'All Group Fixtures'!$E$2:$E$2000,$B23) -> 0 | I23: =G23-H23 -> 0 | J23: =(D23*3)+(E23*1) -> 0 | K23: =COUNTIFS('All Group Fixtures'!$A$2:$A$2000,$A$1,'All Group Fixtures'!$K$2:$K$2000,$B23) -> 0 | L23: =COUNTIFS('All Group Fixtures'!$A$2:$A$2000,$A$1,'All Group Fixtures'!$K$2:$K$2000,$B23,'All Group Fixtures'!$O$2:$O$2000,$B23) -> 0 | M23: =IF(K23=0,0,L23/K23) -> 0 | N23: =COUNTIFS('All Group Fixtures'!$A$2:$A$2000,$A$1,'All Group Fixtures'!$L$2:$L$2000,$B23) -> 3 | O23: =COUNTIFS('All Group Fixtures'!$A$2:$A$2000,$A$1,'All Group Fixtures'!$L$2:$L$2000,$B23,'All Group Fixtures'!$O$2:$O$2000,$B23) -> 0 | P23: =IF(N23=0,0,O23/N23) -> 0
A24: ? | B24: Croatia | C24: =COUNTIFS('All Group Fixtures'!$A$2:$A$2000,$A$1,'All Group Fixtures'!$D$2:$D$2000,$B24)+COUNTIFS('All Group Fixtures'!$A$2:$A$2000,$A$1,'All Group Fixtures'!$E$2:$E$2000,$B24) -> 3 | D24: =COUNTIFS('All Group Fixtures'!$A$2:$A$2000,$A$1,'All Group Fixtures'!$O$2:$O$2000,$B24,'All Group Fixtures'!$D$2:$D$2000,$B24)+COUNTIFS('All Group Fixtures'!$A$2:$A$2000,$A$1,'All Group Fixtures'!$O$2:$O$2000,$B24,'All Group Fixtures'!$E$2:$E$2000,$B24) -> 0 | E24: =COUNTIFS('All Group Fixtures'!$A$2:$A$2000,$A$1,'All Group Fixtures'!$O$2:$O$2000,"Draw",'All Group Fixtures'!$D$2:$D$2000,$B24)+COUNTIFS('All Group Fixtures'!$A$2:$A$2000,$A$1,'All Group Fixtures'!$O$2:$O$2000,"Draw",'All Group Fixtures'!$E$2:$E$2000,$B24) -> 0 | F24: =C24-D24-E24 -> 3 | G24: =SUMIFS('All Group Fixtures'!$F$2:$F$2000,'All Group Fixtures'!$A$2:$A$2000,$A$1,'All Group Fixtures'!$D$2:$D$2000,$B24)+SUMIFS('All Group Fixtures'!$G$2:$G$2000,'All Group Fixtures'!$A$2:$A$2000,$A$1,'All Group Fixtures'!$E$2:$E$2000,$B24) -> 0 | H24: =SUMIFS('All Group Fixtures'!$G$2:$G$2000,'All Group Fixtures'!$A$2:$A$2000,$A$1,'All Group Fixtures'!$D$2:$D$2000,$B24)+SUMIFS('All Group Fixtures'!$F$2:$F$2000,'All Group Fixtures'!$A$2:$A$2000,$A$1,'All Group Fixtures'!$E$2:$E$2000,$B24) -> 0 | I24: =G24-H24 -> 0 | J24: =(D24*3)+(E24*1) -> 0 | K24: =COUNTIFS('All Group Fixtures'!$A$2:$A$2000,$A$1,'All Group Fixtures'!$K$2:$K$2000,$B24) -> 2 | L24: =COUNTIFS('All Group Fixtures'!$A$2:$A$2000,$A$1,'All Group Fixtures'!$K$2:$K$2000,$B24,'All Group Fixtures'!$O$2:$O$2000,$B24) -> 0 | M24: =IF(K24=0,0,L24/K24) -> 0 | N24: =COUNTIFS('All Group Fixtures'!$A$2:$A$2000,$A$1,'All Group Fixtures'!$L$2:$L$2000,$B24) -> 1 | O24: =COUNTIFS('All Group Fixtures'!$A$2:$A$2000,$A$1,'All Group Fixtures'!$L$2:$L$2000,$B24,'All Group Fixtures'!$O$2:$O$2000,$B24) -> 0 | P24: =IF(N24=0,0,O24/N24) -> 0
A25: ? | B25: Nigeria | C25: =COUNTIFS('All Group Fixtures'!$A$2:$A$2000,$A$1,'All Group Fixtures'!$D$2:$D$2000,$B25)+COUNTIFS('All Group Fixtures'!$A$2:$A$2000,$A$1,'All Group Fixtures'!$E$2:$E$2000,$B25) -> 3 | D25: =COUNTIFS('All Group Fixtures'!$A$2:$A$2000,$A$1,'All Group Fixtures'!$O$2:$O$2000,$B25,'All Group Fixtures'!$D$2:$D$2000,$B25)+COUNTIFS('All Group Fixtures'!$A$2:$A$2000,$A$1,'All Group Fixtures'!$O$2:$O$2000,$B25,'All Group Fixtures'!$E$2:$E$2000,$B25) -> 0 | E25: =COUNTIFS('All Group Fixtures'!$A$2:$A$2000,$A$1,'All Group Fixtures'!$O$2:$O$2000,"Draw",'All Group Fixtures'!$D$2:$D$2000,$B25)+COUNTIFS('All Group Fixtures'!$A$2:$A$2000,$A$1,'All Group Fixtures'!$O$2:$O$2000,"Draw",'All Group Fixtures'!$E$2:$E$2000,$B25) -> 0 | F25: =C25-D25-E25 -> 3 | G25: =SUMIFS('All Group Fixtures'!$F$2:$F$2000,'All Group Fixtures'!$A$2:$A$2000,$A$1,'All Group Fixtures'!$D$2:$D$2000,$B25)+SUMIFS('All Group Fixtures'!$G$2:$G$2000,'All Group Fixtures'!$A$2:$A$2000,$A$1,'All Group Fixtures'!$E$2:$E$2000,$B25) -> 0 | H25: =SUMIFS('All Group Fixtures'!$G$2:$G$2000,'All Group Fixtures'!$A$2:$A$2000,$A$1,'All Group Fixtures'!$D$2:$D$2000,$B25)+SUMIFS('All Group Fixtures'!$F$2:$F$2000,'All Group Fixtures'!$A$2:$A$2000,$A$1,'All Group Fixtures'!$E$2:$E$2000,$B25) -> 0 | I25: =G25-H25 -> 0 | J25: =(D25*3)+(E25*1) -> 0 | K25: =COUNTIFS('All Group Fixtures'!$A$2:$A$2000,$A$1,'All Group Fixtures'!$K$2:$K$2000,$B25) -> 1 | L25: =COUNTIFS('All Group Fixtures'!$A$2:$A$2000,$A$1,'All Group Fixtures'!$K$2:$K$2000,$B25,'All Group Fixtures'!$O$2:$O$2000,$B25) -> 0 | M25: =IF(K25=0,0,L25/K25) -> 0 | N25: =COUNTIFS('All Group Fixtures'!$A$2:$A$2000,$A$1,'All Group Fixtures'!$L$2:$L$2000,$B25) -> 2 | O25: =COUNTIFS('All Group Fixtures'!$A$2:$A$2000,$A$1,'All Group Fixtures'!$L$2:$L$2000,$B25,'All Group Fixtures'!$O$2:$O$2000,$B25) -> 0 | P25: =IF(N25=0,0,O25/N25) -> 0
A27: # | B27: Group E | C27: MP | D27: W | E27: D | F27: L | G27: GA | H27: GF | I27: Diff | J27: Pts | K27: Favourites | L27: Strike | M27: % | N27: Outsiders | O27: Strike | P27: %
A28: ? | B28: Brazil | C28: =COUNTIFS('All Group Fixtures'!$A$2:$A$2000,$A$1,'All Group Fixtures'!$D$2:$D$2000,$B28)+COUNTIFS('All Group Fixtures'!$A$2:$A$2000,$A$1,'All Group Fixtures'!$E$2:$E$2000,$B28) -> 3 | D28: =COUNTIFS('All Group Fixtures'!$A$2:$A$2000,$A$1,'All Group Fixtures'!$O$2:$O$2000,$B28,'All Group Fixtures'!$D$2:$D$2000,$B28)+COUNTIFS('All Group Fixtures'!$A$2:$A$2000,$A$1,'All Group Fixtures'!$O$2:$O$2000,$B28,'All Group Fixtures'!$E$2:$E$2000,$B28) -> 0 | E28: =COUNTIFS('All Group Fixtures'!$A$2:$A$2000,$A$1,'All Group Fixtures'!$O$2:$O$2000,"Draw",'All Group Fixtures'!$D$2:$D$2000,$B28)+COUNTIFS('All Group Fixtures'!$A$2:$A$2000,$A$1,'All Group Fixtures'!$O$2:$O$2000,"Draw",'All Group Fixtures'!$E$2:$E$2000,$B28) -> 0 | F28: =C28-D28-E28 -> 3 | G28: =SUMIFS('All Group Fixtures'!$F$2:$F$2000,'All Group Fixtures'!$A$2:$A$2000,$A$1,'All Group Fixtures'!$D$2:$D$2000,$B28)+SUMIFS('All Group Fixtures'!$G$2:$G$2000,'All Group Fixtures'!$A$2:$A$2000,$A$1,'All Group Fixtures'!$E$2:$E$2000,$B28) -> 0 | H28: =SUMIFS('All Group Fixtures'!$G$2:$G$2000,'All Group Fixtures'!$A$2:$A$2000,$A$1,'All Group Fixtures'!$D$2:$D$2000,$B28)+SUMIFS('All Group Fixtures'!$F$2:$F$2000,'All Group Fixtures'!$A$2:$A$2000,$A$1,'All Group Fixtures'!$E$2:$E$2000,$B28) -> 0 | I28: =G28-H28 -> 0 | J28: =(D28*3)+(E28*1) -> 0 | K28: =COUNTIFS('All Group Fixtures'!$A$2:$A$2000,$A$1,'All Group Fixtures'!$K$2:$K$2000,$B28) -> 3 | L28: =COUNTIFS('All Group Fixtures'!$A$2:$A$2000,$A$1,'All Group Fixtures'!$K$2:$K$2000,$B28,'All Group Fixtures'!$O$2:$O$2000,$B28) -> 0 | M28: =IF(K28=0,0,L28/K28) -> 0 | N28: =COUNTIFS('All Group Fixtures'!$A$2:$A$2000,$A$1,'All Group Fixtures'!$L$2:$L$2000,$B28) -> 0 | O28: =COUNTIFS('All Group Fixtures'!$A$2:$A$2000,$A$1,'All Group Fixtures'!$L$2:$L$2000,$B28,'All Group Fixtures'!$O$2:$O$2000,$B28) -> 0 | P28: =IF(N28=0,0,O28/N28) -> 0
A29: ? | B29: Switzerland | C29: =COUNTIFS('All Group Fixtures'!$A$2:$A$2000,$A$1,'All Group Fixtures'!$D$2:$D$2000,$B29)+COUNTIFS('All Group Fixtures'!$A$2:$A$2000,$A$1,'All Group Fixtures'!$E$2:$E$2000,$B29) -> 3 | D29: =COUNTIFS('All Group Fixtures'!$A$2:$A$2000,$A$1,'All Group Fixtures'!$O$2:$O$2000,$B29,'All Group Fixtures'!$D$2:$D$2000,$B29)+COUNTIFS('All Group Fixtures'!$A$2:$A$2000,$A$1,'All Group Fixtures'!$O$2:$O$2000,$B29,'All Group Fixtures'!$E$2:$E$2000,$B29) -> 0 | E29: =COUNTIFS('All Group Fixtures'!$A$2:$A$2000,$A$1,'All Group Fixtures'!$O$2:$O$2000,"Draw",'All Group Fixtures'!$D$2:$D$2000,$B29)+COUNTIFS('All Group Fixtures'!$A$2:$A$2000,$A$1,'All Group Fixtures'!$O$2:$O$2000,"Draw",'All Group Fixtures'!$E$2:$E$2000,$B29) -> 0 | F29: =C29-D29-E29 -> 3 | G29: =SUMIFS('All Group Fixtures'!$F$2:$F$2000,'All Group Fixtures'!$A$2:$A$2000,$A$1,'All Group Fixtures'!$D$2:$D$2000,$B29)+SUMIFS('All Group Fixtures'!$G$2:$G$2000,'All Group Fixtures'!$A$2:$A$2000,$A$1,'All Group Fixtures'!$E$2:$E$2000,$B29) -> 0 | H29: =SUMIFS('All Group Fixtures'!$G$2:$G$2000,'All Group Fixtures'!$A$2:$A$2000,$A$1,'All Group Fixtures'!$D$2:$D$2000,$B29)+SUMIFS('All Group Fixtures'!$F$2:$F$2000,'All Group Fixtures'!$A$2:$A$2000,$A$1,'All Group Fixtures'!$E$2:$E$2000,$B29) -> 0 | I29: =G29-H29 -> 0 | J29: =(D29*3)+(E29*1) -> 0 | K29: =COUNTIFS('All Group Fixtures'!$A$2:$A$2000,$A$1,'All Group Fixtures'!$K$2:$K$2000,$B29) -> 2 | L29: =COUNTIFS('All Group Fixtures'!$A$2:$A$2000,$A$1,'All Group Fixtures'!$K$2:$K$2000,$B29,'All Group Fixtures'!$O$2:$O$2000,$B29) -> 0 | M29: =IF(K29=0,0,L29/K29) -> 0 | N29: =COUNTIFS('All Group Fixtures'!$A$2:$A$2000,$A$1,'All Group Fixtures'!$L$2:$L$2000,$B29) -> 1 | O29: =COUNTIFS('All Group Fixtures'!$A$2:$A$2000,$A$1,'All Group Fixtures'!$L$2:$L$2000,$B29,'All Group Fixtures'!$O$2:$O$2000,$B29) -> 0 | P29: =IF(N29=0,0,O29/N29) -> 0
